Workbook
Name tc: Set!$N$1
Name tc: Ago!$N$1

Sheet Ene
A1: Período de Cálculo: | E1: 44562 | F1: 3.75
A2: PERUPETRO S.A.
A3: DETERMINACION DEL CANON, SOBRECANON y PARTICIPACION (US$)
A4: Correspondiente a Enero 2022
A5: Tipo de Cambio= 3.750
A7: Localidad | C7: Modalidad de Contrato | D7: Calculo del Canon | F7: Volumen Producción / Venta | I7: Canasta o Valor Venta (US$/Unidad) | K7: Deducción de Gastos para determinación de valor de producción en Punto de Fiscalización (US$) | O7: Valor de la Producción (US$) | P7: Canon y Sobrecanon / Participación (US$)
A8: - Lote | D8: Período | E8: Fórmula | F8: Unidades | G8: 1ra. Q | H8: 2da. Q / Mes | I8: 1ra. Q | J8: 2da. Q / Mes | K8: Flete Marítimo | L8: Comercialización | M8: Oleoducto | N8: Fiscalización | P8: Total | Q8: Localidad 1 | S8: Localidad 2
A9: Piura / Tumbes | Q9: Piura | S9: Tumbes
A10: - | B10: I | C10: Servicios | D10: Mes | E10: F1 | F10: Bls | H10: 826 | J10: 84.4782 | O10: 69778.99 | P10: 13083.56 | Q10: 10466.85 | R10: 0.15 | S10: 2616.71 | T10: 0.0375
A11: - | B11: I GAS | C11: Servicios | D11: Mes | E11: F1 | F11: MM BTU | O11: 0 | P11: 0 | Q11: 0 | R11: 0.15 | S11: 0 | T11: 0.0375
A12: - | B12: I (T) | C12: Servicios | D12: Mes | E12: F1 | F12: Bls | G12: 4539 | H12: 10172 | I12: 80.9809 | J12: 87.3395 | N12: 333.0138 | O12: 1255656.7 | P12: 235435.63 | Q12: 188348.5 | R12: 0.15 | S12: 47087.13 | T12: 0.0375
A13: - | B13: I GAS (T) | C13: Servicios | D13: Mes | E13: F1 | F13: MM BTU | G13: 45049.67 | H13: 51899.89 | I13: 3 | J13: 3 | N13: 932.4396 | O13: 289916.24 | P13: 54359.3 | Q13: 43487.44 | R13: 0.15 | S13: 10871.86 | T13: 0.0375
A14: - | B14: II | C14: Licencia | D14: Quincena | E14: F2 | F14: Bls | G14: 12091 | H14: 10787 | I14: 81.2195 | J14: 87.1743 | N14: 856.3237 | O14: 1921517.8 | P14: 360284.59 | Q14: 288227.67 | R14: 0.15 | S14: 72056.92 | T14: 0.0375
A15: - | B15: II-GAS | C15: Servicios | D15: Mes | E15: F1 | F15: MM BTU | G15: 18897.16 | H15: 8771.5 | I15: 2.6775 | J15: 2.6775 | N15: 918.1658 | O15: 73164.674 | P15: 13718.38 | Q15: 10974.7 | R15: 0.15 | S15: 2743.68 | T15: 0.0375
A16: - | B16: III | C16: Licencia | D16: Quincena | E16: F2 | F16: Bls | G16: 6634 | H16: 7572 | I16: 80.9809 | J16: 87.3395 | N16: 613.6971 | O16: 1197948.3 | P16: 224615.3 | Q16: 179692.24 | R16: 0.15 | S16: 44923.06 | T16: 0.0375
A17: - | B17: IV | C17: Licencia | D17: Quincena | E17: F2 | F17: Bls | G17: 29703 | H17: 33545 | I17: 80.9809 | J17: 87.3395 | N17: 1579.4388 | O17: 5333599.8 | P17: 1000050 | Q17: 800039.96 | R17: 0.15 | S17: 200009.99 | T17: 0.0375
A18: - | B18: III (T) | C18: Licencia | D18: Quincena | E18: F2 | F18: Bls | R18: 0.15 | T18: 0.0375
A19: - | B19: IV (T) | C19: Licencia | D19: Quincena | E19: F2 | F19: Bls | R19: 0.15 | T19: 0.0375
A20: - | B20: IV-GAS | C20: Licencia | D20: Quincena | E20: F2 | F20: MM BTU | G20: 4831.53 | H20: 5157.51 | I20: 6.1078 | J20: 6.1078 | O20: 61011.06 | P20: 11439.57 | Q20: 9151.66 | R20: 0.15 | S20: 2287.91 | T20: 0.0375
A21: - | B21: V | C21: Servicios | D21: Mes | E21: F1 | F21: Bls | H21: 2388 | J21: 84.4782 | N21: 723.1151 | O21: 201010.82 | P21: 37689.53 | Q21: 30151.62 | R21: 0.15 | S21: 7537.91 | T21: 0.0375
A22: - | B22: VII/VI | C22: Licencia | D22: Quincena | E22: F2 | F22: Bls | G22: 51473 | H22: 67682 | I22: 80.4309 | J22: 86.7895 | N22: 4405.3001 | O22: 10009701 | P22: 1876819 | Q22: 1501455.2 | R22: 0.15 | S22: 375363.8 | T22: 0.0375
A23: - | B23: VII | C23: Servicios | D23: Mes | E23: F1 | F23: Bls | O23: 0 | P23: 0 | Q23: 0 | R23: 0.15 | S23: 0 | T23: 0.0375
A24: - | B24: VII/VI-GAS | C24: Licencia | D24: Quincena | E24: F2 | F24: MM BTU | G24: 64211.16 | H24: 84856.96 | I24: 0.8 | J24: 0.8 | N24: 1032.3435 | O24: 118222.16 | P24: 22166.65 | Q24: 17733.32 | R24: 0.15 | S24: 4433.33 | T24: 0.0375
A25: - | B25: IX | C25: Licencia | D25: Quincena | E25: F2 | F25: Bls | G25: 2085 | H25: 2729 | I25: 80.9809 | J25: 87.3395 | N25: 356.8018 | O25: 406837.88 | P25: 76282.1 | Q25: 61025.68 | R25: 0.15 | S25: 15256.42 | T25: 0.0375
A26: - | B26: X | C26: Licencia | D26: Quincena | E26: F2 | F26: Bls | G26: 181294 | H26: 191491 | I26: 80.9809 | J26: 87.3395 | N26: 5513.762 | O26: 31400566 | P26: 5887606.1 | Q26: 4710084.9 | R26: 0.15 | S26: 1177521.2 | T26: 0.0375
A27: - | B27: X-GAS | C27: Licencia | D27: Mes | E27: F2 | F27: MM BTU | G27: 256592.52 | H27: 266130.64 | I27: 2.3042 | J27: 2.3042 | N27: 1089.431 | O27: 1203369.3 | P27: 225631.74 | Q27: 180505.39 | R27: 0.15 | S27: 45126.35 | T27: 0.0375
A28: - | B28: XIV | C28: Licencia | D28: Mes | E28: F2 | F28: Bls | O28: 0 | P28: 0 | Q28: 0 | R28: 0.15 | S28: 0 | T28: 0.0375
A29: - | B29: XV | C29: Licencia | D29: Quincena | E29: F2 | F29: Bls | G29: 438 | H29: 473 | I29: 81.2746 | J29: 86.9233 | N29: 390.1013 | O29: 76322.889 | P29: 14310.54 | Q29: 11448.43 | R29: 0.15 | S29: 2862.11 | T29: 0.0375
A30: - | B30: XIII Crudo | C30: Licencia | D30: Quincena | E30: F2 | F30: Bls | G30: 19415 | H30: 29002 | I30: 78.8209 | J30: 85.1795 | N30: 3701.2133 | O30: 3996982.4 | P30: 749434.2 | Q30: 599547.36 | R30: 0.15 | S30: 149886.84 | T30: 0.0375
A31: - | B31: XIII COND | C31: Licencia | D31: Quincena | E31: F2 | F31: Bls | O31: 0 | P31: 0 | Q31: 0 | R31: 0.15 | S31: 0 | T31: 0.0375
A32: - | B32: XIII Gas -A | C32: Licencia | D32: Quincena | E32: F2 | F32: MM BTU | G32: 116255.91 | H32: 176845.03 | I32: 1.5 | J32: 1.5 | N32: 1536.6225 | O32: 438114.8 | P32: 82146.52 | Q32: 65717.22 | R32: 0.15 | S32: 16429.3 | T32: 0.0375
A33: - | B33: XIII Gas -B | C33: Licencia | D33: Quincena | E33: F2 | F33: MM BTU | G33: 105118.14 | H33: 98915.22 | I33: 3.3981 | J33: 3.4271 | O33: 696194.3 | P33: 130536.43 | Q33: 104429.15 | R33: 0.15 | S33: 26107.29 | T33: 0.0375
A34: - | B34: XIII Gas Lantera | C34: Licencia | D34: Quincena | E34: F2 | F34: MM BTU | O34: 0 | P34: 0 | Q34: 0 | R34: 0.15 | S34: 0 | T34: 0.0375
A35: - | B35: XIII Gas Expectativa | C35: Licencia | D35: Quincena | E35: F2 | F35: MM BTU | O35: 0 | P35: 0 | Q35: 0 | R35: 0.15 | S35: 0 | T35: 0.0375
A36: - | B36: XIII Gas Paita | C36: Licencia | D36: Quincena | E36: F2 | F36: MM BTU | G36: 11015.53 | H36: 14257.29 | I36: 3.2604 | J36: 3.14 | O36: 80682.92 | P36: 15128.05 | Q36: 12102.44 | R36: 0.15 | S36: 3025.61 | T36: 0.0375
A39: - | B39: Z-2B | C39: Servicios | D39: Mes | E39: F1 | F39: Bls | H39: 172371 | J39: 85.5724 | N39: 1189.3375 | O39: 14749011 | P39: 2765439.5 | Q39: 2212351.6 | R39: 0.15 | S39: 553087.91 | T39: 0.0375
A40: - | B40: Z-2B GAS | C40: Servicios | D40: Mes | E40: F1 | F40: MM BTU | H40: 350250.76 | J40: 7.9799 | N40: 1051.3744 | O40: 2793914.7 | P40: 523859 | Q40: 419087.2 | R40: 0.15 | S40: 104771.8 | T40: 0.0375
A41: - | B41: XX | C41: Licencia | D41: Quincena | E41: F2 | F41: Bls | G41: 128 | H41: 163 | I41: 80.9809 | J41: 87.3395 | N41: 228.3528 | O41: 24373.547 | P41: 4570.04 | Q41: 914.01 | R41: 0.0375 | S41: 3656.03 | T41: 0.15
A42: - | B42: Z1 Crudo | C42: Licencia | D42: Quincena | E42: F2 | F42: Bls | O42: 0 | P42: 0 | Q42: 0 | R42: 0.0375 | S42: 0 | T42: 0.15
A43: - | B43: Z1 Gas | C43: Licencia | D43: Quincena | E43: F2 | F43: MM BTU | O43: 0 | P43: 0 | Q43: 0 | R43: 0.0375 | S43: 0 | T43: 0.15
...

Sheet Feb
A1: Período de Cálculo: | E1: 44593 | F1: 3.736 | S1: ,
A2: PERUPETRO S.A.
A3: DETERMINACION DEL CANON, SOBRECANON y PARTICIPACION (US$)
A4: Correspondiente a Febrero 2022
A5: Tipo de Cambio= 3.736
A7: Localidad | C7: Modalidad de Contrato | D7: Calculo del Canon | F7: Volumen Producción / Venta | I7: Canasta o Valor Venta (US$/Unidad) | K7: Deducción de Gastos para determinación de valor de producción en Punto de Fiscalización (US$) | O7: Valor de la Producción (US$) | P7: Canon y Sobrecanon / Participación (US$)
A8: - Lote | D8: Período | E8: Fórmula | F8: Unidades | G8: 1ra. Q | H8: 2da. Q / Mes | I8: 1ra. Q | J8: 2da. Q / Mes | K8: Flete Marítimo | L8: Comercialización | M8: Oleoducto | N8: Fiscalización | P8: Total | Q8: Localidad 1 | S8: Localidad 2
A9: Piura / Tumbes | Q9: Piura | S9: Tumbes
A10: - | B10: I | C10: Servicios | D10: Mes | E10: F1 | F10: Bls | O10: 0 | P10: 0 | Q10: 0 | R10: 0.15 | S10: 0 | T10: 0.0375
A11: - | B11: I GAS | C11: Servicios | D11: Mes | E11: F1 | F11: MM BTU | O11: 0 | P11: 0 | Q11: 0 | R11: 0.15 | S11: 0 | T11: 0.0375
A12: - | B12: I (T) | C12: Licencia | D12: Quincena | E12: F1 | F12: Bls | G12: 4575 | H12: 9569 | I12: 92.2457 | J12: 94.2228 | N12: 339.93 | O12: 1323302.1 | P12: 248119.15 | Q12: 198495.32 | R12: 0.15 | S12: 49623.83 | T12: 0.0375
A13: - | B13: I GAS (T) | C13: Licencia | D13: Quincena | E13: F1 | F13: MM BTU | G13: 45119.926 | H13: 41908.219 | I13: 3 | J13: 3 | N13: 945.89 | O13: 260138.55 | P13: 48775.98 | Q13: 39020.78 | R13: 0.15 | S13: 9755.2 | T13: 0.0375
A14: - | B14: II | C14: Licencia | D14: Quincena | E14: F2 | F14: Bls | G14: 6115 | H14: 8168 | I14: 91.4711 | J14: 94.7473 | N14: 871.9899 | O14: 1332369.7 | P14: 249819.33 | Q14: 199855.46 | R14: 0.15 | S14: 49963.87 | T14: 0.0375
A15: - | B15: II-GAS | C15: Servicios | D15: Mes | E15: F1 | F15: MM BTU | G15: 18346.436 | H15: 15010.972 | I15: 2.6775 | J15: 2.6775 | N15: 931.1067 | O15: 88383.353 | P15: 16571.88 | Q15: 13257.5 | R15: 0.15 | S15: 3314.38 | T15: 0.0375
A16: - | B16: III | C16: Licencia | D16: Quincena | E16: F2 | F16: Bls | G16: 7450 | H16: 5393 | I16: 92.2457 | J16: 94.2228 | N16: 620.7369 | O16: 1194753.3 | P16: 224016.24 | Q16: 179212.99 | R16: 0.15 | S16: 44803.25 | T16: 0.0375
A17: - | B17: IV | C17: Licencia | D17: Quincena | E17: F2 | F17: Bls | G17: 31149 | H17: 25735 | I17: 92.2457 | J17: 94.2228 | N17: 1606.0388 | O17: 5296579 | P17: 993108.57 | Q17: 794486.85 | R17: 0.15 | S17: 198621.71 | T17: 0.0375
A18: - | B18: III (T) | C18: Licencia | D18: Quincena | E18: F2 | F18: Bls | R18: 0.15 | T18: 0.0375
A19: - | B19: IV (T) | C19: Licencia | D19: Quincena | E19: F2 | F19: Bls | R19: 0.15 | T19: 0.0375
A20: - | B20: IV-GAS | C20: Licencia | D20: Quincena | E20: F2 | F20: Bls | G20: 4541.1349 | H20: 3370.7184 | I20: 9.94 | J20: 9.94 | O20: 78643.82 | P20: 14745.72 | Q20: 11796.57 | R20: 0.15 | S20: 2949.14 | T20: 0.0375
A21: - | B21: V | C21: Servicios | D21: Mes | E21: F1 | F21: Bls | H21: 1703 | J21: 93.2343 | N21: 734.0489 | O21: 158043.96 | P21: 29633.24 | Q21: 23706.59 | R21: 0.15 | S21: 5926.65 | T21: 0.0375
A22: - | B22: VII/VI | C22: Licencia | D22: Quincena | E22: F2 | F22: Bls | G22: 49836 | H22: 52502 | I22: 91.6957 | J22: 93.6728 | N22: 4473.2562 | O22: 9483283 | P22: 1778115.6 | Q22: 1422492.4 | R22: 0.15 | S22: 355623.11 | T22: 0.0375
A23: - | B23: VII | C23: Servicios | D23: Mes | E23: F1 | F23: Bls | O23: 0 | P23: 0 | Q23: 0 | R23: 0.15 | S23: 0 | T23: 0.0375
A24: - | B24: VII/VI-GAS | C24: Licencia | D24: Quincena | E24: F2 | F24: MM BTU | G24: 79232.06 | H24: 69839.98 | I24: 0.8 | J24: 0.8 | N24: 1049.3456 | O24: 118208.28 | P24: 22164.05 | Q24: 17731.24 | R24: 0.15 | S24: 4432.81 | T24: 0.0375
A25: - | B25: IX | C25: Licencia | D25: Quincena | E25: F2 | F25: Bls | G25: 2015 | H25: 2427 | I25: 92.2457 | J25: 94.2228 | N25: 364.5597 | O25: 414189.27 | P25: 77660.49 | Q25: 62128.39 | R25: 0.15 | S25: 15532.1 | T25: 0.0375
A26: - | B26: X | C26: Licencia | D26: Quincena | E26: F2 | F26: Bls | G26: 164988 | H26: 165480 | I26: 92.2457 | J26: 94.2228 | N26: 5606.3528 | O26: 30805816 | P26: 5776090.5 | Q26: 4620872.4 | R26: 0.15 | S26: 1155218.1 | T26: 0.0375
A27: - | B27: X-GAS | C27: Licencia | D27: Mes | E27: F2 | F27: MM BTU | G27: 249423.79 | H27: 211941.04 | I27: 2.189 | J27: 2.189 | N27: 1103.5329 | O27: 1008824.1 | P27: 189154.52 | Q27: 151323.61 | R27: 0.15 | S27: 37830.9 | T27: 0.0375
A28: - | B28: XIV | C28: Licencia | D28: Mes | E28: F2 | F28: Bls | O28: 0 | P28: 0 | Q28: 0 | R28: 0.15 | S28: 0 | T28: 0.0375
A29: - | B29: XV | C29: Licencia | D29: Quincena | E29: F2 | F29: Bls | G29: 150 | H29: 643 | I29: 90.3599 | J29: 93.5457 | N29: 394.1181 | O29: 73309.762 | P29: 13745.58 | Q29: 10996.46 | R29: 0.15 | S29: 2749.12 | T29: 0.0375
A30: - | B30: XIII Crudo | C30: Licencia | D30: Quincena | E30: F2 | F30: Bls | G30: 17487 | H30: 22293 | I30: 89.8957 | J30: 91.8728 | N30: 3758.9146 | O30: 3616367.5 | P30: 678068.91 | Q30: 542455.13 | R30: 0.15 | S30: 135613.78 | T30: 0.0375
A31: - | B31: XIII COND | C31: Licencia | D31: Quincena | E31: F2 | F31: Bls | O31: 0 | P31: 0 | Q31: 0 | R31: 0.15 | S31: 0 | T31: 0.0375
A32: - | B32: XIII Gas-A | C32: Licencia | D32: Quincena | E32: F2 | F32: MM BTU | G32: 163708.77 | H32: 143775.38 | I32: 1.61 | J32: 1.61 | N32: 1561.6999 | O32: 493487.78 | P32: 92528.96 | Q32: 74023.17 | R32: 0.15 | S32: 18505.79 | T32: 0.0375
A33: - | B33: XIII Gas-B | C33: Licencia | D33: Quincena | E33: F2 | F33: MM BTU | G33: 83801.806 | H33: 102606.09 | I33: 3.6149 | J33: 3.3345 | O33: 645075.15 | P33: 120951.59 | Q33: 96761.27 | R33: 0.15 | S33: 24190.32 | T33: 0.0375
A34: - | B34: XIII Gas Lantera | C34: Licencia | D34: Quincena | E34: F2 | F34: MM BTU | O34: 0 | P34: 0 | Q34: 0 | R34: 0.15 | S34: 0 | T34: 0.0375
A35: - | B35: XIII Gas Expectativa | C35: Licencia | D35: Quincena | E35: F2 | F35: MM BTU | O35: 0 | P35: 0 | Q35: 0 | R35: 0.15 | S35: 0 | T35: 0.0375
A36: - | B36: XIII Gas Paita | C36: Licencia | D36: Quincena | E36: F2 | F36: MM BTU | G36: 14995.04 | H36: 15559.33 | I36: 3.1749 | J36: 3.2336 | O36: 97920.4 | P36: 18360.08 | Q36: 14688.06 | R36: 0.15 | S36: 3672.02 | T36: 0.0375
A37: - | B37: XIII Gas Efe-01 | C37: Licencia | D37: Quincena | E37: F2 | F37: MM BTU | P37: 0 | Q37: 0 | R37: 0.15 | S37: 0 | T37: 0.0375
A38: - | B38: XIII Gas Efe-02 | C38: Licencia | D38: Quincena | E38: F2 | F38: MM BTU | G38: 588.84 | H38: 567.24 | I38: 3 | J38: 3 | O38: 3468.24 | P38: 650.3 | Q38: 520.24 | R38: 0.15 | S38: 130.06 | T38: 0.0375
A39: - | B39: Z-2B | C39: Servicios | D39: Mes | E39: F1 | F39: Bls | H39: 159846 | J39: 94.1015 | N39: 1206.9912 | O39: 15040541 | P39: 2820101.5 | Q39: 2256081.2 | R39: 0.15 | S39: 564020.3 | T39: 0.0375
A40: - | B40: Z-2B GAS | C40: Servicios | D40: Mes | E40: F1 | F40: MM BTU | H40: 185166.58 | J40: 8.6913 | N40: 1064.1234 | O40: 1608274.2 | P40: 301551.41 | Q40: 241241.13 | R40: 0.15 | S40: 60310.28 | T40: 0.0375
A41: - | B41: XX | C41: Licencia | D41: Quincena | E41: F2 | F41: Bls | H41: 310 | J41: 94.2228 | N41: 231.543 | O41: 28977.527 | P41: 5433.29 | Q41: 1086.66 | R41: 0.0375 | S41: 4346.63 | T41: 0.15
...

Sheet Mar
A1: Período de Cálculo: | E1: 44621 | F1: 3.709
A2: PERUPETRO S.A.
A3: DETERMINACION DEL CANON, SOBRECANON y PARTICIPACION (US$)
A4: Correspondiente a Marzo 2022
A5: Tipo de Cambio= 3.709
A7: Localidad | C7: Modalidad de Contrato | D7: Calculo del Canon | F7: Volumen Producción / Venta | I7: Canasta o Valor Venta (US$/Unidad) | K7: Deducción de Gastos para determinación de valor de producción en Punto de Fiscalización (US$) | O7: Valor de la Producción (US$) | P7: Canon y Sobrecanon / Participación (US$)
A8: - Lote | D8: Período | E8: Fórmula | F8: Unidades | G8: 1ra. Q | H8: 2da. Q / Mes | I8: 1ra. Q | J8: 2da. Q / Mes | K8: Flete Marítimo | L8: Comercialización | M8: Oleoducto | N8: Fiscalización | P8: Total | Q8: Localidad 1 | S8: Localidad 2
A9: Piura / Tumbes | Q9: Piura | S9: Tumbes
A10: - | B10: I | C10: Servicios | D10: Mes | E10: F1 | F10: Bls | O10: 0 | P10: 0 | Q10: 0 | R10: 0.15 | S10: 0 | T10: 0.0375
A11: - | B11: I GAS | C11: Servicios | D11: Mes | E11: F1 | F11: MM BTU | O11: 0 | P11: 0 | Q11: 0 | R11: 0.15 | S11: 0 | T11: 0.0375
A12: - | B12: I (T) | C12: Licencia | D12: Quincena | E12: F1 | F12: Bls | G12: 5023 | H12: 10690 | I12: 107.5241 | J12: 102.0001 | N12: 355.7377 | O12: 1630118.9 | P12: 305647.29 | Q12: 244517.83 | R12: 0.15 | S12: 61129.46 | T12: 0.0375
A13: - | B13: I GAS (T) | C13: Licencia | D13: Quincena | E13: F1 | F13: MM BTU | G13: 50111.66 | H13: 55425.88 | I13: 3 | J13: 3 | N13: 1000.515 | O13: 315612.1 | P13: 59177.27 | Q13: 47341.82 | R13: 0.15 | S13: 11835.45 | T13: 0.0375
A14: - | B14: II | C14: Licencia | D14: Quincena | E14: F2 | F14: Bls | G14: 6499 | H14: 7353 | I14: 112.4745 | J14: 109.4624 | N14: 922.6958 | O14: 1534926.1 | P14: 287798.65 | Q14: 230238.92 | R14: 0.15 | S14: 57559.73 | T14: 0.0375
A15: - | B15: II-GAS | C15: Servicios | D15: Mes | E15: F1 | F15: MM BTU | G15: 18406.43 | H15: 17992.92 | I15: 2.6775 | J15: 2.6775 | N15: 983.8385 | O15: 96475.422 | P15: 18089.14 | Q15: 14471.31 | R15: 0.15 | S15: 3617.83 | T15: 0.0375
A16: - | B16: III | C16: Licencia | D16: Quincena | E16: F2 | F16: Bls | G16: 6084 | H16: 7711 | I16: 107.5241 | J16: 102.0001 | N16: 655.8932 | O16: 1440043.5 | P16: 270008.16 | Q16: 216006.52 | R16: 0.15 | S16: 54001.63 | T16: 0.0375
A17: - | B17: IV | C17: Licencia | D17: Quincena | E17: F2 | F17: Bls | G17: 29912 | H17: 30160 | I17: 107.5241 | J17: 102.0001 | N17: 1695.3138 | O17: 6290888.6 | P17: 1179541.6 | Q17: 943633.29 | R17: 0.15 | S17: 235908.32 | T17: 0.0375
A18: - | B18: III (T) | C18: Licencia | D18: Quincena | E18: F2 | F18: Bls
A19: - | B19: IV (T) | C19: Licencia | D19: Quincena | E19: F2 | F19: Bls
A20: - | B20: IV-GAS | C20: Licencia | D20: Quincena | E20: F2 | F20: Bls | G20: 3240.59 | H20: 4599.55 | I20: 10.9575 | J20: 10.9575 | O20: 85908.33 | P20: 16107.81 | Q20: 12886.25 | R20: 0.15 | S20: 3221.56 | T20: 0.0375
A21: - | B21: V | C21: Servicios | D21: Mes | E21: F1 | F21: Bls | H21: 2740 | J21: 104.642 | N21: 778.176 | O21: 285940.9 | P21: 53613.92 | Q21: 42891.14 | R21: 0.15 | S21: 10722.78 | T21: 0.0375
A22: - | B22: VII/VI | C22: Licencia | D22: Quincena | E22: F2 | F22: Bls | G22: 49542 | H22: 63337 | I22: 106.9741 | J22: 101.4501 | N22: 4724.6459 | O22: 11720531 | P22: 2197599.6 | Q22: 1758079.7 | R22: 0.15 | S22: 439519.92 | T22: 0.0375
A23: - | B23: VII | C23: Servicios | D23: Mes | E23: F1 | F23: Bls | O23: 0 | P23: 0 | Q23: 0 | R23: 0.15 | S23: 0 | T23: 0.0375
A24: - | B24: VII/VI-GAS | C24: Licencia | D24: Quincena | E24: F2 | F24: MM BTU | G24: 78135.51 | H24: 83426.5 | I24: 0.8 | J24: 0.8 | N24: 1106.1239 | O24: 128143.49 | P24: 24026.9 | Q24: 19221.52 | R24: 0.15 | S24: 4805.38 | T24: 0.0375
A25: - | B25: IX | C25: Licencia | D25: Quincena | E25: F2 | F25: Bls | G25: 2091 | H25: 2747 | I25: 107.5241 | J25: 102.0001 | N25: 383.53 | O25: 504643.63 | P25: 94620.68 | Q25: 75696.54 | R25: 0.15 | S25: 18924.14 | T25: 0.0375
A26: - | B26: X | C26: Licencia | D26: Quincena | E26: F2 | F26: Bls | G26: 177288 | H26: 187760 | I26: 107.5241 | J26: 102.0001 | N26: 5914.1443 | O26: 38208357 | P26: 7164067 | Q26: 5731253.6 | R26: 0.15 | S26: 1432813.4 | T26: 0.0375
A27: - | B27: X-GAS | C27: Licencia | D27: Mes | E27: F2 | F27: MM BTU | G27: 245814.06 | H27: 260565.77 | I27: 2.2619 | J27: 2.2619 | N27: 1167.2666 | O27: 1144213.3 | P27: 214539.99 | Q27: 171631.99 | R27: 0.15 | S27: 42908 | T27: 0.0375
A28: - | B28: XIV | C28: Licencia | D28: Mes | E28: F2 | F28: Bls | O28: 0 | P28: 0 | Q28: 0 | R28: 0.15 | S28: 0 | T28: 0.0375
A29: - | B29: XV | C29: Licencia | D29: Quincena | E29: F2 | F29: Bls | G29: 460 | H29: 425 | I29: 109.79 | J29: 108.9004 | N29: 416.8804 | O29: 96369.19 | P29: 18069.22 | Q29: 14455.38 | R29: 0.15 | S29: 3613.84 | T29: 0.0375
A30: - | B30: XIII Crudo | C30: Licencia | D30: Quincena | E30: F2 | F30: Bls | G30: 16970 | H30: 41143 | I30: 105.4441 | J30: 99.9201 | N30: 3974.2597 | O30: 5896424.8 | P30: 1105579.6 | Q30: 884463.72 | R30: 0.15 | S30: 221115.93 | T30: 0.0375
A31: - | B31: XIII COND | C31: Licencia | D31: Quincena | E31: F2 | F31: Bls | O31: 0 | P31: 0 | Q31: 0 | R31: 0.15 | S31: 0 | T31: 0.0375
A32: - | B32: XIII Gas-A | C32: Licencia | D32: Quincena | E32: F2 | F32: MM BTU | G32: 165650.16 | H32: 158800.18 | I32: 1.61 | J32: 1.61 | N32: 1650.8476 | O32: 520714.2 | P32: 97633.91 | Q32: 78107.13 | R32: 0.15 | S32: 19526.78 | T32: 0.0375
A33: - | B33: XIII Gas-B | C33: Licencia | D33: Quincena | E33: F2 | F33: MM BTU | G33: 80673.99 | H33: 119330.17 | I33: 3.7167 | J33: 3.584 | O33: 727520.35 | P33: 136410.07 | Q33: 109128.05 | R33: 0.15 | S33: 27282.01 | T33: 0.0375
A34: - | B34: XIII Gas Lantera | C34: Licencia | D34: Quincena | E34: F2 | F34: MM BTU | O34: 0 | P34: 0 | Q34: 0 | R34: 0.15 | S34: 0 | T34: 0.0375
A35: - | B35: XIII Gas Expectativa | C35: Licencia | D35: Quincena | E35: F2 | F35: MM BTU | O35: 0 | P35: 0 | Q35: 0 | R35: 0.15 | S35: 0 | T35: 0.0375
A36: - | B36: XIII Gas Paita | C36: Licencia | D36: Quincena | E36: F2 | F36: MM BTU | G36: 21258.19 | H36: 24809.69 | I36: 3.2705 | J36: 3.4106 | O36: 154140.84 | P36: 28901.41 | Q36: 23121.13 | R36: 0.15 | S36: 5780.28 | T36: 0.0375
B37: XIII Gas Efe-01 | R37: 0.15 | T37: 0.0375
A38: - | B38: XIII Gas Efe-02 | C38: Licencia | D38: Quincena | E38: F2 | F38: MM BTU | G38: 728.76 | H38: 907.37 | I38: 3 | J38: 3 | O38: 4908.39 | P38: 920.32 | Q38: 736.26 | R38: 0.15 | S38: 184.06 | T38: 0.0375
A39: - | B39: Z-2B | C39: Servicios | D39: Mes | E39: F1 | F39: Bls | H39: 166905 | J39: 112.463 | N39: 1278.4335 | O39: 18769359 | P39: 3519254.7 | Q39: 2815403.8 | R39: 0.15 | S39: 703850.95 | T39: 0.0375
A40: - | B40: Z-2B GAS | C40: Servicios | D40: Mes | E40: F1 | F40: MM BTU | H40: 181131.3 | J40: 9.9553 | N40: 1122.8004 | O40: 1802093.6 | P40: 337892.56 | Q40: 270314.04 | R40: 0.15 | S40: 67578.51 | T40: 0.0375
A41: - | B41: XX | C41: Licencia | D41: Quincena | E41: F2 | F41: Bls | G41: 159 | H41: 171 | I41: 107.5241 | J41: 102.0001 | N41: 244.5708 | O41: 34293.779 | P41: 6430.08 | Q41: 1286.02 | R41: 0.0375 | S41: 5144.07 | T41: 0.15
...

Sheet Abr
A1: Período de Cálculo: | E1: 44652 | F1: 3.772
A2: PERUPETRO S.A.
A3: DETERMINACION DEL CANON, SOBRECANON y PARTICIPACION (US$)
A4: Correspondiente a Abril 2022
A5: Tipo de Cambio= 3.772
A7: Localidad | C7: Modalidad de Contrato | D7: Calculo del Canon | F7: Volumen Producción / Venta | I7: Canasta o Valor Venta (US$/Unidad) | K7: Deducción de Gastos para determinación de valor de producción en Punto de Fiscalización (US$) | O7: Valor de la Producción (US$) | P7: Canon y Sobrecanon / Participación (US$)
A8: - Lote | D8: Período | E8: Fórmula | F8: Unidades | G8: 1ra. Q | H8: 2da. Q / Mes | I8: 1ra. Q | J8: 2da. Q / Mes | K8: Flete Marítimo | L8: Comercialización | M8: Oleoducto | N8: Fiscalización | P8: Total | Q8: Localidad 1 | S8: Localidad 2
A9: Piura / Tumbes | Q9: Piura | S9: Tumbes
A10: - | B10: I | C10: Servicios | D10: Mes | E10: F1 | F10: Bls | O10: 0 | P10: 0 | Q10: 0 | R10: 0.15 | S10: 0 | T10: 0.0375
A11: - | B11: I GAS | C11: Servicios | D11: Mes | E11: F1 | F11: MM BTU | O11: 0 | P11: 0 | Q11: 0 | R11: 0.15 | S11: 0 | T11: 0.0375
A12: - | B12: I (T) | C12: Licencia | D12: Quincena | E12: F1 | F12: Bls | G12: 5274 | H12: 10117 | I12: 90.6453 | J12: 91.8196 | N12: 409.18 | O12: 1406593 | P12: 263736.19 | Q12: 210988.95 | R12: 0.15 | S12: 52747.24 | T12: 0.0375
A13: - | B13: I GAS (T) | C13: Licencia | D13: Quincena | E13: F1 | F13: MM BTU | G13: 51146.02 | H13: 50668.5 | I13: 3 | J13: 3 | N13: 1150.83 | O13: 304292.73 | P13: 57054.89 | Q13: 45643.91 | R13: 0.15 | S13: 11410.98 | T13: 0.0375
A14: - | B14: II | C14: Licencia | D14: Quincena | E14: F2 | F14: Bls | G14: 6862 | H14: 7519 | I14: 102.6472 | J14: 104.6102 | N14: 1061.321 | O14: 1489867.9 | P14: 279350.22 | Q14: 223480.18 | R14: 0.15 | S14: 55870.04 | T14: 0.0375
A15: - | B15: II-GAS | C15: Servicios | D15: Mes | E15: F1 | F15: MM BTU | G15: 14960.26 | H15: 19748.05 | I15: 2.6775 | J15: 2.6775 | N15: 1131.6493 | O15: 91799.851 | P15: 17212.47 | Q15: 13769.98 | R15: 0.15 | S15: 3442.49 | T15: 0.0375
A16: - | B16: III | C16: Licencia | D16: Quincena | E16: F2 | F16: Bls | G16: 3487 | H16: 6701 | I16: 90.6453 | J16: 91.8196 | N16: 754.432 | O16: 930608.87 | P16: 174489.16 | Q16: 139591.33 | R16: 0.15 | S16: 34897.83 | T16: 0.0375
A17: - | B17: IV | C17: Licencia | D17: Quincena | E17: F2 | F17: Bls | G17: 29703 | H17: 30424 | I17: 90.6453 | J17: 91.8196 | N17: 1950.0182 | O17: 5484006.8 | P17: 1028251.3 | Q17: 822601.03 | R17: 0.15 | S17: 205650.26 | T17: 0.0375
A18: - | B18: III (T) | C18: Licencia | D18: Quincena | E18: F2 | F18: Bls | H18: 3149 | J18: 90.1653 | O18: 283930.53 | P18: 53236.97 | Q18: 42589.58 | R18: 0.15 | S18: 10647.39 | T18: 0.0375
A19: - | B19: IV (T) | C19: Licencia | D19: Quincena | E19: F2 | F19: Bls | H19: 1297 | J19: 101.5201 | O19: 131671.57 | P19: 24688.42 | Q19: 19750.74 | R19: 0.15 | S19: 4937.68 | T19: 0.0375
A20: - | B20: IV-GAS | C20: Licencia | D20: Quincena | E20: F2 | F20: Bls | G20: 32143.78 | H20: 31410.17 | I20: 12.5103 | J20: 12.5103 | O20: 795078.98 | P20: 149077.31 | Q20: 119261.85 | R20: 0.15 | S20: 29815.46 | T20: 0.0375
A21: - | B21: V | C21: Servicios | D21: Mes | E21: F1 | F21: Bls | H21: 3761 | J21: 91.2016 | N21: 895.0912 | O21: 342114.13 | P21: 64146.4 | Q21: 51317.12 | R21: 0.15 | S21: 12829.28 | T21: 0.0375
A22: - | B22: VII/VI | C22: Licencia | D22: Quincena | E22: F2 | F22: Bls | G22: 49608 | H22: 61686 | I22: 90.0953 | J22: 91.2696 | N22: 5434.4815 | O22: 10094070 | P22: 1892638.1 | Q22: 1514110.5 | R22: 0.15 | S22: 378527.61 | T22: 0.0375
A23: - | B23: VII | C23: Servicios | D23: Mes | E23: F1 | F23: Bls | O23: 0 | P23: 0 | Q23: 0 | R23: 0.15 | S23: 0 | T23: 0.0375
A24: - | B24: VII/VI-GAS | C24: Licencia | D24: Quincena | E24: F2 | F24: MM BTU | G24: 70506.21 | H24: 77681.18 | I24: 0.8 | J24: 0.8 | N24: 1272.3085 | O24: 117277.6 | P24: 21989.55 | Q24: 17591.64 | R24: 0.15 | S24: 4397.91 | T24: 0.0375
A25: - | B25: IX | C25: Licencia | D25: Quincena | E25: F2 | F25: Bls | G25: 2079 | H25: 2522 | I25: 90.6453 | J25: 91.8196 | N25: 441.1516 | O25: 419579.46 | P25: 78671.15 | Q25: 62936.92 | R25: 0.15 | S25: 15734.23 | T25: 0.0375
A26: - | B26: X | C26: Licencia | D26: Quincena | E26: F2 | F26: Bls | G26: 175665 | H26: 171678 | I26: 90.6453 | J26: 91.8196 | N26: 6802.6915 | O26: 31679809 | P26: 5939964.2 | Q26: 4751971.4 | R26: 0.15 | S26: 1187992.9 | T26: 0.0375
A27: - | B27: X-GAS | C27: Licencia | D27: Mes | E27: F2 | F27: MM BTU | G27: 246240.45 | H27: 247734.71 | I27: 2.3274 | J27: 2.3274 | N27: 1342.6368 | O27: 1148335.1 | P27: 215312.84 | Q27: 172250.27 | R27: 0.15 | S27: 43062.57 | T27: 0.0375
A28: - | B28: XIV | C28: Licencia | D28: Mes | E28: F2 | F28: Bls | O28: 0 | P28: 0 | Q28: 0 | R28: 0.15 | S28: 0 | T28: 0.0375
A29: - | B29: XV | C29: Licencia | D29: Quincena | E29: F2 | F29: Bls | G29: 456 | H29: 415 | I29: 102.8385 | J29: 104.9242 | N29: 479.5128 | O29: 89958.387 | P29: 16867.2 | Q29: 13493.76 | R29: 0.15 | S29: 3373.44 | T29: 0.0375
A30: - | B30: XIII Crudo | C30: Licencia | D30: Quincena | E30: F2 | F30: Bls | G30: 31482 | H30: 43287 | I30: 88.7453 | J30: 89.9196 | N30: 4571.3601 | O30: 6681657.9 | P30: 1252810.9 | Q30: 1002248.7 | R30: 0.15 | S30: 250562.17 | T30: 0.0375
A31: - | B31: XIII COND | C31: Licencia | D31: Quincena | E31: F2 | F31: Bls | O31: 0 | P31: 0 | Q31: 0 | R31: 0.15 | S31: 0 | T31: 0.0375
A32: - | B32: XIII Gas - A | C32: Licencia | D32: Quincena | E32: F2 | F32: MM BTU | G32: 160804.44 | H32: 164798.6 | I32: 1.61 | J32: 1.61 | N32: 1898.8692 | O32: 522322.03 | P32: 97935.38 | Q32: 78348.3 | R32: 0.15 | S32: 19587.08 | T32: 0.0375
A33: - | B33: XIII Gas - B | C33: Licencia | D33: Quincena | E33: F2 | F33: MM BTU | G33: 93348.49 | H33: 87836.3 | I33: 3.5889 | J33: 3.6594 | O33: 656446.56 | P33: 123083.73 | Q33: 98466.98 | R33: 0.15 | S33: 24616.75 | T33: 0.0375
A34: - | B34: XIII Gas Lantera | C34: Licencia | D34: Quincena | E34: F2 | F34: MM BTU | O34: 0 | P34: 0 | Q34: 0 | R34: 0.15 | S34: 0 | T34: 0.0375
A35: - | B35: XIII Gas Expectativa | C35: Licencia | D35: Quincena | E35: F2 | F35: MM BTU | O35: 0 | P35: 0 | Q35: 0 | R35: 0.15 | S35: 0 | T35: 0.0375
A36: - | B36: XIII Gas Paita | C36: Licencia | D36: Quincena | E36: F2 | F36: MM BTU | G36: 21410.95 | H36: 19263.65 | I36: 3.4 | J36: 3.397 | O36: 138235.85 | P36: 25919.22 | Q36: 20735.38 | R36: 0.15 | S36: 5183.84 | T36: 0.0375
A37: - | B37: XIII Gas Efe-01 | C37: Licencia | D37: Quincena | E37: F2 | F37: MM BTU | G37: 348.32 | I37: 2.3 | O37: 801.14 | P37: 150.21 | Q37: 120.17 | R37: 0.15 | S37: 30.04 | T37: 0.0375
A38: - | B38: XIII Gas Efe-02 | C38: Licencia | D38: Quincena | E38: F2 | F38: MM BTU | G38: 896.44 | H38: 997.3669 | I38: 3 | J38: 3 | O38: 5681.42 | P38: 1065.27 | Q38: 852.21 | R38: 0.15 | S38: 213.05 | T38: 0.0375
A39: - | B39: Z-2B | C39: Servicios | D39: Mes | E39: F1 | F39: Bls | H39: 160288 | J39: 105.917 | N39: 1470.5055 | O39: 16975754 | P39: 3182953.8 | Q39: 2546363 | R39: 0.15 | S39: 636590.76 | T39: 0.0375
A40: - | B40: Z-2B GAS | C40: Servicios | D40: Mes | E40: F1 | F40: MM BTU | H40: 331873.65 | J40: 9.3633 | N40: 1291.4878 | O40: 3106141.1 | P40: 582401.45 | Q40: 465921.16 | R40: 0.15 | S40: 116480.29 | T40: 0.0375
A41: - | B41: XX | C41: Licencia | D41: Quincena | E41: F2 | F41: Bls | G41: 151 | H41: 149 | I41: 90.6453 | J41: 91.8196 | N41: 281.3158 | O41: 27087.244 | P41: 5078.86 | Q41: 1015.77 | R41: 0.0375 | S41: 4063.09 | T41: 0.15
...

Sheet May
A1: Período de Cálculo: | E1: 44682 | F1: 3.728
A2: PERUPETRO S.A.
A3: DETERMINACION DEL CANON, SOBRECANON y PARTICIPACION (US$)
A4: Correspondiente a Mayo 2022
A5: Tipo de Cambio= 3.728
A7: Localidad | C7: Modalidad de Contrato | D7: Calculo del Canon | F7: Volumen Producción / Venta | I7: Canasta o Valor Venta (US$/Unidad) | K7: Deducción de Gastos para determinación de valor de producción en Punto de Fiscalización (US$) | O7: Valor de la Producción (US$) | P7: Canon y Sobrecanon / Participación (US$)
A8: - Lote | D8: Período | E8: Fórmula | F8: Unidades | G8: 1ra. Q | H8: 2da. Q / Mes | I8: 1ra. Q | J8: 2da. Q / Mes | K8: Flete Marítimo | L8: Comercialización | M8: Oleoducto | N8: Fiscalización | P8: Total | Q8: Localidad 1 | S8: Localidad 2
A9: Piura / Tumbes | Q9: Piura | S9: Tumbes
A10: - | B10: I | C10: Servicios | D10: Mes | E10: F1 | F10: Bls | O10: 0 | P10: 0 | Q10: 0 | R10: 0.15 | S10: 0 | T10: 0.0375
A11: - | B11: I GAS | C11: Servicios | D11: Mes | E11: F1 | F11: MM BTU | O11: 0 | P11: 0 | Q11: 0 | R11: 0.15 | S11: 0 | T11: 0.0375
A12: - | B12: I (T) | C12: Licencia | D12: Quincena | E12: F1 | F12: Bls | G12: 5302 | H12: 10459 | I12: 95.3171 | J12: 101.63 | N12: 345.3493 | O12: 1567974.1 | P12: 293995.14 | Q12: 235196.11 | R12: 0.15 | S12: 58799.03 | T12: 0.0375
A13: - | B13: I GAS (T) | C13: Licencia | D13: Quincena | E13: F1 | F13: MM BTU | G13: 51905.16 | H13: 54127.44 | I13: 3 | J13: 3 | N13: 971.2948 | O13: 317126.51 | P13: 59461.22 | Q13: 47568.98 | R13: 0.15 | S13: 11892.24 | T13: 0.0375
A14: - | B14: II | C14: Licencia | D14: Quincena | E14: F2 | F14: Bls | G14: 6160 | H14: 6575 | I14: 107.4261 | J14: 112.1093 | N14: 895.7513 | O14: 1397967.7 | P14: 262118.94 | Q14: 209695.15 | R14: 0.15 | S14: 52423.79 | T14: 0.0375
A15: - | B15: II-GAS | C15: Servicios | D15: Mes | E15: F1 | F15: MM BTU | G15: 36706.9 | H15: 42658.01 | I15: 2.6775 | J15: 2.6775 | N15: 955.1093 | O15: 211544.43 | P15: 39664.58 | Q15: 31731.66 | R15: 0.15 | S15: 7932.92 | T15: 0.0375
A16: - | B16: III | C16: Licencia | D16: Quincena | E16: F2 | F16: Bls | G16: 6500 | H16: 7956 | I16: 95.3171 | J16: 101.63 | N16: 636.7386 | O16: 1427492.7 | P16: 267654.88 | Q16: 214123.9 | R16: 0.15 | S16: 53530.98 | T16: 0.0375
A17: - | B17: IV | C17: Licencia | D17: Quincena | E17: F2 | F17: Bls | G17: 31685 | H17: 35935 | I17: 95.3171 | J17: 101.63 | N17: 1645.8079 | O17: 6670550.6 | P17: 1250728.2 | Q17: 1000582.6 | R17: 0.15 | S17: 250145.65 | T17: 0.0375
A18: - | B18: III (T) | C18: Licencia | D18: Quincena | E18: F2 | F18: Bls | R18: 0.15 | T18: 0.0375
A19: - | B19: IV (T) | C19: Licencia | D19: Quincena | E19: F2 | F19: Bls | R19: 0.15 | T19: 0.0375
A20: - | B20: IV-GAS | C20: Licencia | D20: Quincena | E20: F2 | F20: Bls | G20: 33719.55 | H20: 48700.62 | I20: 4.5181 | J20: 4.5181 | O20: 372382.57 | P20: 69821.73 | Q20: 55857.39 | R20: 0.15 | S20: 13964.35 | T20: 0.0375
A21: - | B21: V | C21: Servicios | D21: Mes | E21: F1 | F21: Bls | H21: 4255 | J21: 98.9719 | N21: 755.4518 | O21: 420369.98 | P21: 78819.37 | Q21: 63055.5 | R21: 0.15 | S21: 15763.87 | T21: 0.0375
A22: - | B22: VII/VI | C22: Licencia | D22: Quincena | E22: F2 | F22: Bls | G22: 50318 | H22: 65226 | I22: 94.7671 | J22: 101.08 | N22: 4586.6766 | O22: 11356948 | P22: 2129427.8 | Q22: 1703542.2 | R22: 0.15 | S22: 425885.56 | T22: 0.0375
A23: - | B23: VII | C23: Servicios | D23: Mes | E23: F1 | F23: Bls | O23: 0 | P23: 0 | Q23: 0 | R23: 0.15 | S23: 0 | T23: 0.0375
A24: - | B24: VII/VI-GAS | C24: Licencia | D24: Quincena | E24: F2 | F24: MM BTU | G24: 75957.01 | H24: 84035.1 | I24: 0.8 | J24: 0.8 | N24: 1073.8225 | O24: 126919.87 | P24: 23797.48 | Q24: 19037.98 | R24: 0.15 | S24: 4759.5 | T24: 0.0375
A25: - | B25: IX | C25: Licencia | D25: Quincena | E25: F2 | F25: Bls | G25: 2063 | H25: 2671 | I25: 95.3171 | J25: 101.63 | N25: 372.3307 | O25: 467720.58 | P25: 87697.61 | Q25: 70158.09 | R25: 0.15 | S25: 17539.52 | T25: 0.0375
A26: - | B26: X | C26: Licencia | D26: Quincena | E26: F2 | F26: Bls | G26: 170657 | H26: 181222 | I26: 95.3171 | J26: 101.63 | N26: 5741.4405 | O26: 34678381 | P26: 6502196.4 | Q26: 5201757.1 | R26: 0.15 | S26: 1300439.3 | T26: 0.0375
A27: - | B27: X-GAS | C27: Licencia | D27: Mes | E27: F2 | F27: MM BTU | G27: 252146.13 | H27: 263478.45 | I27: 2.4748 | J27: 2.4748 | N27: 1133.1805 | O27: 1274934.5 | P27: 239050.22 | Q27: 191240.18 | R27: 0.15 | S27: 47810.04 | T27: 0.0375
A28: - | B28: XIV | C28: Licencia | D28: Mes | E28: F2 | F28: Bls | O28: 0 | P28: 0 | Q28: 0 | R28: 0.15 | S28: 0 | T28: 0.0375
A29: - | B29: XV | C29: Licencia | D29: Quincena | E29: F2 | F29: Bls | G29: 420 | H29: 469 | I29: 106.9382 | J29: 111.7698 | N29: 404.7073 | O29: 96929.373 | P29: 18174.26 | Q29: 14539.41 | R29: 0.15 | S29: 3634.85 | T29: 0.0375
A30: - | B30: XIII Crudo | C30: Licencia | D30: Quincena | E30: F2 | F30: Bls | G30: 30675 | H30: 43364 | I30: 93.3471 | J30: 99.66 | N30: 3858.2034 | O30: 7181220.3 | P30: 1346478.8 | Q30: 1077183.1 | R30: 0.15 | S30: 269295.76 | T30: 0.0375
A31: - | B31: XIII COND | C31: Licencia | D31: Quincena | E31: F2 | F31: Bls | O31: 0 | P31: 0 | Q31: 0 | R31: 0.15 | S31: 0 | T31: 0.0375
A32: - | B32: XIII Gas - A | C32: Licencia | D32: Quincena | E32: F2 | F32: MM BTU | G32: 160977.09 | H32: 178576.12 | I32: 1.61 | J32: 1.61 | N32: 1602.6409 | O32: 545078.04 | P32: 102202.13 | Q32: 81761.71 | R32: 0.15 | S32: 20440.43 | T32: 0.0375
A33: - | B33: XIII Gas - B | C33: Licencia | D33: Quincena | E33: F2 | F33: MM BTU | G33: 57251.251 | H33: 89598.703 | I33: 3.6642 | J33: 3.62 | O33: 534127.34 | P33: 100148.88 | Q33: 80119.1 | R33: 0.15 | S33: 20029.78 | T33: 0.0375
A34: - | B34: XIII Gas Lantera | C34: Licencia | D34: Quincena | E34: F2 | F34: MM BTU | O34: 0 | P34: 0 | Q34: 0 | R34: 0.15 | S34: 0 | T34: 0.0375
A35: - | B35: XIII Gas Expectativa | C35: Licencia | D35: Quincena | E35: F2 | F35: MM BTU | O35: 0 | P35: 0 | Q35: 0 | R35: 0.15 | S35: 0 | T35: 0.0375
A36: - | B36: XIII Gas Paita | C36: Licencia | D36: Quincena | E36: F2 | F36: MM BTU | G36: 19087.149 | H36: 23496.592 | I36: 3.3952 | J36: 3.3877 | O36: 144404.1 | P36: 27075.77 | Q36: 21660.62 | R36: 0.15 | S36: 5415.15 | T36: 0.0375
B37: XIII Gas Efe-01 | C37: Licencia | D37: Quincena | E37: F2 | F37: MM BTU | H37: 1804.8142 | J37: 2.3 | O37: 4151.07 | P37: 778.33 | Q37: 622.66 | R37: 0.15 | S37: 155.67 | T37: 0.0375
A38: - | B38: XIII Gas Efe-02 | C38: Licencia | D38: Quincena | E38: F2 | F38: MM BTU | G38: 1083.367 | H38: 1304.8214 | I38: 3 | J38: 3 | O38: 7164.56 | P38: 1343.36 | Q38: 1074.68 | R38: 0.15 | S38: 268.67 | T38: 0.0375
A39: - | B39: Z-2B | C39: Servicios | D39: Mes | E39: F1 | F39: Bls | H39: 155802 | J39: 111.9595 | N39: 1241.1006 | O39: 17442273 | P39: 3270426.2 | Q39: 2616340.9 | R39: 0.15 | S39: 654085.23 | T39: 0.0375
A40: - | B40: Z-2B GAS | C40: Servicios | D40: Mes | E40: F1 | F40: MM BTU | H40: 386604.63 | J40: 9.6363 | N40: 1090.0108 | O40: 3724348.2 | P40: 698315.29 | Q40: 558652.23 | R40: 0.15 | S40: 139663.06 | T40: 0.0375
A41: - | B41: XX | C41: Licencia | D41: Quincena | E41: F2 | F41: Bls | G41: 136 | H41: 153 | I41: 95.3171 | J41: 101.63 | N41: 237.43 | O41: 28275.09 | P41: 5301.58 | Q41: 1060.32 | R41: 0.0375 | S41: 4241.26 | T41: 0.15
...

Sheet Jun
A1: Período de Cálculo: | E1: 44713 | F1: 3.878
A2: PERUPETRO S.A.
A3: DETERMINACION DEL CANON, SOBRECANON y PARTICIPACION (US$)
A4: Correspondiente a Junio 2022
A5: Tipo de Cambio= 3.878
A7: Localidad | C7: Modalidad de Contrato | D7: Calculo del Canon | F7: Volumen Producción / Venta | I7: Canasta o Valor Venta (US$/Unidad) | K7: Deducción de Gastos para determinación de valor de producción en Punto de Fiscalización (US$) | O7: Valor de la Producción (US$) | P7: Canon y Sobrecanon / Participación (US$)
A8: - Lote | D8: Período | E8: Fórmula | F8: Unidades | G8: 1ra. Q | H8: 2da. Q / Mes | I8: 1ra. Q | J8: 2da. Q / Mes | K8: Flete Marítimo | L8: Comercialización | M8: Oleoducto | N8: Fiscalización | P8: Total | Q8: Localidad 1 | S8: Localidad 2
A9: Piura / Tumbes | Q9: Piura | S9: Tumbes
A10: - | B10: I | C10: Servicios | D10: Mes | E10: F1 | F10: Bls | O10: 0 | P10: 0 | Q10: 0 | R10: 0.15 | S10: 0 | T10: 0.0375
A11: - | B11: I GAS | C11: Servicios | D11: Mes | E11: F1 | F11: MM BTU | O11: 0 | P11: 0 | Q11: 0 | R11: 0.15 | S11: 0 | T11: 0.0375
A12: - | B12: I (T) | C12: Licencia | D12: Quincena | E12: F1 | F12: Bls | G12: 5626 | H12: 9335 | I12: 109.9129 | J12: 103.1167 | N12: 315.99 | O12: 1580648.4 | P12: 296371.57 | Q12: 237097.26 | R12: 0.15 | S12: 59274.31 | T12: 0.0375
A13: - | B13: I GAS (T) | C13: Licencia | D13: Quincena | E13: F1 | F13: MM BTU | G13: 49723.37 | H13: 48547.65 | I13: 3 | J13: 3 | N13: 888.72 | O13: 293924.34 | P13: 55110.81 | Q13: 44088.65 | R13: 0.15 | S13: 11022.16 | T13: 0.0375
A14: - | B14: II | C14: Licencia | D14: Quincena | E14: F2 | F14: Bls | G14: 7265 | H14: 6338 | I14: 120.0363 | J14: 112.483 | N14: 819.5979 | O14: 1584161.4 | P14: 297030.26 | Q14: 237624.21 | R14: 0.15 | S14: 59406.05 | T14: 0.0375
A15: - | B15: II-GAS | C15: Servicios | D15: Mes | E15: F1 | F15: MM BTU | G15: 35672.07 | H15: 21786.86 | I15: 2.6775 | J15: 2.6775 | N15: 873.9112 | O15: 152972.38 | P15: 28682.32 | Q15: 22945.86 | R15: 0.15 | S15: 5736.46 | T15: 0.0375
A16: - | B16: III | C16: Licencia | D16: Quincena | E16: F2 | F16: Bls | G16: 7791 | H16: 7679 | I16: 109.9129 | J16: 103.1167 | N16: 582.6057 | O16: 1647581.9 | P16: 308921.61 | Q16: 247137.29 | R16: 0.15 | S16: 61784.32 | T16: 0.0375
A17: - | B17: IV | C17: Licencia | D17: Quincena | E17: F2 | F17: Bls | G17: 33895 | H17: 36390 | I17: 109.9129 | J17: 103.1167 | N17: 1505.8903 | O17: 7476408.6 | P17: 1401826.6 | Q17: 1121461.3 | R17: 0.15 | S17: 280365.32 | T17: 0.0375
A18: - | B18: III (T) | C18: Licencia | D18: Quincena | E18: F2 | F18: Bls | O18: 0 | P18: 0 | Q18: 0 | R18: 0.15 | S18: 0 | T18: 0.0375
A19: - | B19: IV (T) | C19: Licencia | D19: Quincena | E19: F2 | F19: Bls | O19: 0 | P19: 0 | Q19: 0 | R19: 0.15 | S19: 0 | T19: 0.0375
A20: - | B20: IV-GAS | C20: Licencia | D20: Quincena | E20: F2 | F20: Bls | G20: 41673.4 | H20: 44743.49 | I20: 4.3501 | J20: 4.3501 | O20: 375922.12 | P20: 70485.4 | Q20: 56388.32 | R20: 0.15 | S20: 14097.08 | T20: 0.0375
A21: - | B21: V | C21: Servicios | D21: Mes | E21: F1 | F21: Bls | H21: 3582 | J21: 106.175 | N21: 691.2272 | O21: 379627.62 | P21: 71180.18 | Q21: 56944.14 | R21: 0.15 | S21: 14236.04 | T21: 0.0375
A22: - | B22: VII/VI | C22: Licencia | D22: Quincena | E22: F2 | F22: Bls | G22: 48602 | H22: 61078 | I22: 109.3629 | J22: 102.5667 | N22: 4196.7415 | O22: 11575628 | P22: 2170430.2 | Q22: 1736344.2 | R22: 0.15 | S22: 434086.04 | T22: 0.0375
A23: - | B23: VII | C23: Servicios | D23: Mes | E23: F1 | F23: Bls | O23: 0 | P23: 0 | Q23: 0 | R23: 0.15 | S23: 0 | T23: 0.0375
A24: - | B24: VII/VI-GAS | C24: Licencia | D24: Quincena | E24: F2 | F24: MM BTU | G24: 78477.74 | H24: 77612.89 | I24: 0.8 | J24: 1.0933 | N24: 982.5326 | O24: 146653.83 | P24: 27497.59 | Q24: 21998.07 | R24: 0.15 | S24: 5499.52 | T24: 0.0375
A25: - | B25: IX | C25: Licencia | D25: Quincena | E25: F2 | F25: Bls | G25: 2081 | H25: 2408 | I25: 109.9129 | J25: 103.1167 | N25: 340.6762 | O25: 476693.07 | P25: 89379.95 | Q25: 71503.96 | R25: 0.15 | S25: 17875.99 | T25: 0.0375
A26: - | B26: X | C26: Licencia | D26: Quincena | E26: F2 | F26: Bls | G26: 146880 | H26: 187167 | I26: 109.9129 | J26: 103.1167 | N26: 5253.3394 | O26: 35438797 | P26: 6644774.4 | Q26: 5315819.5 | R26: 0.15 | S26: 1328954.9 | T26: 0.0375
A27: - | B27: X-GAS | C27: Licencia | D27: Mes | E27: F2 | F27: MM BTU | G27: 243978.27 | H27: 248076.24 | I27: 2.4702 | J27: 2.4702 | N27: 1036.8433 | O27: 1214436.2 | P27: 227706.79 | Q27: 182165.43 | R27: 0.15 | S27: 45541.36 | T27: 0.0375
A28: - | B28: XIV | C28: Licencia | D28: Mes | E28: F2 | F28: Bls | O28: 0 | P28: 0 | Q28: 0 | R28: 0.15 | S28: 0 | T28: 0.0375
A29: - | B29: XV | C29: Licencia | D29: Quincena | E29: F2 | F29: Bls | G29: 349 | H29: 468 | I29: 119.0874 | J29: 111.3367 | N29: 370.3003 | O29: 93296.78 | P29: 17493.15 | Q29: 13994.52 | R29: 0.15 | S29: 3498.63 | T29: 0.0375
A30: - | B30: XIII Crudo | C30: Licencia | D30: Quincena | E30: F2 | F30: Bls | G30: 31905 | H30: 30231 | I30: 107.8929 | J30: 101.0967 | N30: 3530.2037 | O30: 6495047.1 | P30: 1217821.3 | Q30: 974257.07 | R30: 0.15 | S30: 243564.27 | T30: 0.0375
A31: - | B31: XIII COND | C31: Licencia | D31: Quincena | E31: F2 | F31: Bls | O31: 0 | P31: 0 | Q31: 0 | R31: 0.15 | S31: 0 | T31: 0.0375
A32: - | B32: XIII Gas - A | C32: Licencia | D32: Quincena | E32: F2 | F32: MM BTU | G32: 167367.88 | H32: 166626.11 | I32: 1.61 | J32: 1.61 | N32: 1466.3916 | O32: 536263.94 | P32: 100549.49 | Q32: 80439.59 | R32: 0.15 | S32: 20109.9 | T32: 0.0375
A33: - | B33: XIII Gas - B | C33: Licencia | D33: Quincena | E33: F2 | F33: MM BTU | G33: 103826.52 | H33: 87816.35 | I33: 3.5988 | J33: 3.5735 | O33: 687462.61 | P33: 128899.24 | Q33: 103119.39 | R33: 0.15 | S33: 25779.85 | T33: 0.0375
A34: - | B34: XIII Gas Lantera | C34: Licencia | D34: Quincena | E34: F2 | F34: MM BTU | O34: 0 | P34: 0 | Q34: 0 | R34: 0.15 | S34: 0 | T34: 0.0375
A35: - | B35: XIII Gas Expectativa | C35: Licencia | D35: Quincena | E35: F2 | F35: MM BTU | O35: 0 | P35: 0 | Q35: 0 | R35: 0.15 | S35: 0 | T35: 0.0375
A36: - | B36: XIII Gas Paita | C36: Licencia | D36: Quincena | E36: F2 | F36: MM BTU | G36: 23748.88 | H36: 25263.38 | I36: 3.3875 | J36: 3.3836 | O36: 165930.5 | P36: 31111.97 | Q36: 24889.58 | R36: 0.15 | S36: 6222.39 | T36: 0.0375
B37: XIII Gas Efe-01 | C37: Licencia | D37: Quincena | E37: F2 | F37: MM BTU | G37: 5437.95 | H37: 641.21 | I37: 2.3 | J37: 2.3001 | O37: 13982.14 | P37: 2621.65 | Q37: 2097.32 | R37: 0.15 | S37: 524.33 | T37: 0.0375
A38: - | B38: XIII Gas Efe-02 | C38: Licencia | D38: Quincena | E38: F2 | F38: MM BTU | G38: 1323.08 | H38: 1426.8667 | I38: 3 | J38: 3 | O38: 8249.84 | P38: 1546.85 | Q38: 1237.48 | R38: 0.15 | S38: 309.37 | T38: 0.0375
A39: - | B39: Z-2B | C39: Servicios | D39: Mes | E39: F1 | F39: Bls | H39: 170949 | J39: 117.5032 | N39: 1135.5901 | O39: 20085919 | P39: 3766109.8 | Q39: 3012887.8 | R39: 0.15 | S39: 753221.96 | T39: 0.0375
A40: - | B40: Z-2B GAS | C40: Servicios | D40: Mes | E40: F1 | F40: MM BTU | H40: 424150.64 | J40: 10.0651 | N40: 997.342 | O40: 4268121.3 | P40: 800272.74 | Q40: 640218.19 | R40: 0.15 | S40: 160054.55 | T40: 0.0375
A41: - | B41: XX | C41: Licencia | D41: Quincena | E41: F2 | F41: Bls | G41: 154 | H41: 145 | I41: 109.9129 | J41: 103.1167 | N41: 217.2428 | O41: 31661.267 | P41: 5936.49 | Q41: 1187.3 | R41: 0.0375 | S41: 4749.19 | T41: 0.15
...

Sheet Jul
A1: Período de Cálculo: | E1: 44743 | F1: 3.847
A2: PERUPETRO S.A.
A3: DETERMINACION DEL CANON, SOBRECANON y PARTICIPACION (US$)
A4: Correspondiente a Julio 2022
A5: Tipo de Cambio= 3.847
A7: Localidad | C7: Modalidad de Contrato | D7: Calculo del Canon | F7: Volumen Producción / Venta | I7: Canasta o Valor Venta (US$/Unidad) | K7: Deducción de Gastos para determinación de valor de producción en Punto de Fiscalización (US$) | O7: Valor de la Producción (US$) | P7: Canon y Sobrecanon / Participación (US$)
A8: - Lote | D8: Período | E8: Fórmula | F8: Unidades | G8: 1ra. Q | H8: 2da. Q / Mes | I8: 1ra. Q | J8: 2da. Q / Mes | K8: Flete Marítimo | L8: Comercialización | M8: Oleoducto | N8: Fiscalización | P8: Total | Q8: Localidad 1 | S8: Localidad 2
A9: Piura / Tumbes | Q9: Piura | S9: Tumbes
A10: - | B10: I | C10: Servicios | D10: Mes | E10: F1 | F10: Bls | O10: 0 | P10: 0 | Q10: 0 | R10: 0.15 | S10: 0 | T10: 0.0375
A11: - | B11: I GAS | C11: Servicios | D11: Mes | E11: F1 | F11: MM BTU | O11: 0 | P11: 0 | Q11: 0 | R11: 0.15 | S11: 0 | T11: 0.0375
A12: - | B12: I (T) | C12: Licencia | D12: Quincena | E12: F1 | F12: Bls | G12: 4733 | H12: 10152 | I12: 95.5027 | J12: 102.0698 | N12: 323.06 | O12: 1487903.8 | P12: 278981.97 | Q12: 223185.57 | R12: 0.15 | S12: 55796.39 | T12: 0.0375
A13: - | B13: I GAS (T) | C13: Licencia | D13: Quincena | E13: F1 | F13: MM BTU | G13: 47136.75 | H13: 48776.51 | I13: 3 | J13: 3 | N13: 908.61 | O13: 286831.17 | P13: 53780.84 | Q13: 43024.68 | R13: 0.15 | S13: 10756.17 | T13: 0.0375
A14: - | B14: II | C14: Licencia | D14: Quincena | E14: F2 | F14: Bls | G14: 5792 | H14: 6249 | I14: 104.788 | J14: 104.4745 | N14: 837.9414 | O14: 1258955.3 | P14: 236054.12 | Q14: 188843.3 | R14: 0.15 | S14: 47210.82 | T14: 0.0375
A15: - | B15: II-GAS | C15: Servicios | D15: Mes | E15: F1 | F15: MM BTU | G15: 19977.07 | H15: 21984.69 | I15: 2.6775 | J15: 2.6775 | N15: 893.4675 | O15: 111459.14 | P15: 20898.59 | Q15: 16718.87 | R15: 0.15 | S15: 4179.72 | T15: 0.0375
A16: - | B16: III | C16: Licencia | D16: Quincena | E16: F2 | F16: Bls | G16: 7029 | H16: 9085 | I16: 95.5027 | J16: 102.0698 | N16: 595.6459 | O16: 1597997 | P16: 299624.43 | Q16: 239699.54 | R16: 0.15 | S16: 59924.89 | T16: 0.0375
A17: - | B17: IV | C17: Licencia | D17: Quincena | E17: F2 | F17: Bls | G17: 32747 | H17: 46607 | I17: 95.5027 | J17: 102.0698 | N17: 1539.5898 | O17: 7883054.5 | P17: 1478072.7 | Q17: 1182458.2 | R17: 0.15 | S17: 295614.54 | T17: 0.0375
A18: - | B18: III (T) | C18: Licencia | D18: Quincena | E18: F2 | F18: Bls | O18: 0 | P18: 0 | Q18: 0 | R18: 0.15 | S18: 0 | T18: 0.0375
A19: - | B19: IV (T) | C19: Licencia | D19: Quincena | E19: F2 | F19: Bls | O19: 0 | P19: 0 | Q19: 0 | R19: 0.15 | S19: 0 | T19: 0.0375
A20: - | B20: IV-GAS | C20: Licencia | D20: Quincena | E20: F2 | F20: Bls | G20: 55372.78 | H20: 54362.78 | I20: 3.4511 | J20: 3.4511 | O20: 378708.39 | P20: 71007.82 | Q20: 56806.26 | R20: 0.15 | S20: 14201.56 | T20: 0.0375
A21: - | B21: V | C21: Servicios | D21: Mes | E21: F1 | F21: Bls | H21: 3282 | J21: 98.7863 | N21: 706.6955 | O21: 323509.94 | P21: 60658.11 | Q21: 48526.49 | R21: 0.15 | S21: 12131.62 | T21: 0.0375
A22: - | B22: VII/VI | C22: Licencia | D22: Quincena | E22: F2 | F22: Bls | G22: 52513 | H22: 59172 | I22: 94.9527 | J22: 101.5198 | N22: 4290.665 | O22: 10989090 | P22: 2060454.4 | Q22: 1648363.5 | R22: 0.15 | S22: 412090.88 | T22: 0.0375
A23: - | B23: VII | C23: Servicios | D23: Mes | E23: F1 | F23: Bls | O23: 0 | P23: 0 | Q23: 0 | R23: 0.15 | S23: 0 | T23: 0.0375
A24: - | B24: VII/VI-GAS | C24: Licencia | D24: Quincena | E24: F2 | F24: MM BTU | G24: 78037.59 | H24: 82703.85 | I24: 1.8394 | J24: 2.7985 | N24: 1004.5223 | O24: 373984.54 | P24: 70122.1 | Q24: 56097.68 | R24: 0.15 | S24: 14024.42 | T24: 0.0375
A25: - | B25: IX | C25: Licencia | D25: Quincena | E25: F2 | F25: Bls | G25: 2054 | H25: 2624 | I25: 95.5027 | J25: 102.0698 | N25: 348.3006 | O25: 463645.41 | P25: 86933.51 | Q25: 69546.81 | R25: 0.15 | S25: 17386.7 | T25: 0.0375
A26: - | B26: X | C26: Licencia | D26: Quincena | E26: F2 | F26: Bls | G26: 167020 | H26: 175331 | I26: 95.5027 | J26: 102.0698 | N26: 5370.9045 | O26: 33841490 | P26: 6345279.4 | Q26: 5076223.5 | R26: 0.15 | S26: 1269055.9 | T26: 0.0375
A27: - | B27: X-GAS | C27: Licencia | D27: Mes | E27: F2 | F27: MM BTU | G27: 246553.1 | H27: 258740.98 | I27: 2.4843 | J27: 2.4843 | N27: 1060.0459 | O27: 1254242 | P27: 235170.38 | Q27: 188136.31 | R27: 0.15 | S27: 47034.08 | T27: 0.0375
A28: - | B28: XIV | C28: Licencia | D28: Mes | E28: F2 | F28: Bls | O28: 0 | P28: 0 | Q28: 0 | R28: 0.15 | S28: 0 | T28: 0.0375
A29: - | B29: XV | C29: Licencia | D29: Quincena | E29: F2 | F29: Bls | G29: 386 | H29: 483 | I29: 102.6022 | J29: 103.6125 | N29: 378.5885 | O29: 89270.701 | P29: 16738.26 | Q29: 13390.61 | R29: 0.15 | S29: 3347.65 | T29: 0.0375
A30: - | B30: XIII Crudo | C30: Licencia | D30: Quincena | E30: F2 | F30: Bls | G30: 28720 | H30: 28580 | I30: 93.4927 | J30: 100.0598 | N30: 3609.2102 | O30: 5541210.2 | P30: 1038976.9 | Q30: 831181.53 | R30: 0.15 | S30: 207795.38 | T30: 0.0375
A31: - | B31: XIII COND | C31: Licencia | D31: Quincena | E31: F2 | F31: Bls | O31: 0 | P31: 0 | Q31: 0 | R31: 0.15 | S31: 0 | T31: 0.0375
A32: - | B32: XIII Gas - A | C32: Licencia | D32: Quincena | E32: F2 | F32: MM BTU | G32: 133225.33 | H32: 131510.54 | I32: 1.61 | J32: 1.61 | N32: 1499.2076 | O32: 424725.54 | P32: 79636.04 | Q32: 63708.83 | R32: 0.15 | S32: 15927.21 | T32: 0.0375
A33: - | B33: XIII Gas - B | C33: Licencia | D33: Quincena | E33: F2 | F33: MM BTU | G33: 83684.424 | H33: 81174.338 | I33: 3.7471 | J33: 3.7927 | O33: 621443.82 | P33: 116520.72 | Q33: 93216.57 | R33: 0.15 | S33: 23304.14 | T33: 0.0375
A34: - | B34: XIII Gas Lantera | C34: Licencia | D34: Quincena | E34: F2 | F34: MM BTU | O34: 0 | P34: 0 | Q34: 0 | R34: 0.15 | S34: 0 | T34: 0.0375
A35: - | B35: XIII Gas Expectativa | C35: Licencia | D35: Quincena | E35: F2 | F35: MM BTU | O35: 0 | P35: 0 | Q35: 0 | R35: 0.15 | S35: 0 | T35: 0.0375
A36: - | B36: XIII Gas Paita | C36: Licencia | D36: Quincena | E36: F2 | F36: MM BTU | G36: 20174.482 | H36: 16611.758 | I36: 3.3943 | J36: 3.3944 | O36: 124865.19 | P36: 23412.22 | Q36: 18729.78 | R36: 0.15 | S36: 4682.44 | T36: 0.0375
A37: - | B37: XIII Gas Efe-01 | C37: Licencia | D37: Quincena | E37: F2 | F37: MM BTU | G37: 11290.108 | H37: 909.0989 | I37: 2.3942 | J37: 2.3 | O37: 29121.71 | P37: 5460.32 | Q37: 4368.26 | R37: 0.15 | S37: 1092.06 | T37: 0.0375
A38: - | B38: XIII Gas Efe-02 | C38: Licencia | D38: Quincena | E38: F2 | F38: MM BTU | G38: 1495.2522 | H38: 1736.6278 | I38: 3 | J38: 3 | O38: 9695.64 | P38: 1817.93 | Q38: 1454.35 | R38: 0.15 | S38: 363.59 | T38: 0.0375
A39: - | B39: Z-2B | C39: Servicios | D39: Mes | E39: F1 | F39: Bls | H39: 165440 | J39: 105.1238 | N39: 1161.0013 | O39: 17390520 | P39: 3260722.6 | Q39: 2608578.1 | R39: 0.15 | S39: 652144.52 | T39: 0.0375
A40: - | B40: Z-2B GAS | C40: Servicios | D40: Mes | E40: F1 | F40: MM BTU | H40: 467017.55 | J40: 9.424 | N40: 1019.6637 | O40: 4400153.7 | P40: 825028.82 | Q40: 660023.06 | R40: 0.15 | S40: 165005.76 | T40: 0.0375
A41: - | B41: XX | C41: Licencia | D41: Quincena | E41: F2 | F41: Bls | G41: 155 | H41: 155 | I41: 95.5027 | J41: 102.0698 | N41: 222.1045 | O41: 30401.635 | P41: 5700.31 | Q41: 1140.06 | R41: 0.0375 | S41: 4560.25 | T41: 0.15
...

Sheet Ago
A1: Período de Cálculo: | E1: 44774 | F1: 3.871
A2: PERUPETRO S.A.
A3: DETERMINACION DEL CANON, SOBRECANON y PARTICIPACION (US$)
A4: Correspondiente a Agosto 2022
A5: Tipo de Cambio= 3.871
A7: Localidad | C7: Modalidad de Contrato | D7: Calculo del Canon | F7: Volumen Producción / Venta | I7: Canasta o Valor Venta (US$/Unidad) | K7: Deducción de Gastos para determinación de valor de producción en Punto de Fiscalización (US$) | O7: Valor de la Producción (US$) | P7: Canon y Sobrecanon / Participación (US$)
A8: - Lote | D8: Período | E8: Fórmula | F8: Unidades | G8: 1ra. Q | H8: 2da. Q / Mes | I8: 1ra. Q | J8: 2da. Q / Mes | K8: Flete Marítimo | L8: Comercialización | M8: Oleoducto | N8: Fiscalización | P8: Total | Q8: Localidad 1 | S8: Localidad 2
A9: Piura / Tumbes | Q9: Piura | S9: Tumbes
A10: - | B10: I | C10: Servicios | D10: Mes | E10: F1 | F10: Bls | O10: 0 | P10: 0 | Q10: 0 | R10: 0.15 | S10: 0 | T10: 0.0375
A11: - | B11: I GAS | C11: Servicios | D11: Mes | E11: F1 | F11: MM BTU | O11: 0 | P11: 0 | Q11: 0 | R11: 0.15 | S11: 0 | T11: 0.0375
A12: - | B12: I (T) | C12: Licencia | D12: Quincena | E12: F1 | F12: Bls | G12: 5220 | H12: 9197 | I12: 98.0823 | J12: 95.8076 | N12: 298.6764 | O12: 1392833.4 | P12: 261156.27 | Q12: 208925.02 | R12: 0.15 | S12: 52231.25 | T12: 0.0375
A13: - | B13: I GAS (T) | C13: Licencia | D13: Quincena | E13: F1 | F13: MM BTU | G13: 47113.74 | H13: 51109.61 | I13: 3 | J13: 3 | N13: 840.0234 | O13: 293830.03 | P13: 55093.13 | Q13: 44074.5 | R13: 0.15 | S13: 11018.63 | T13: 0.0375
A14: - | B14: II | C14: Licencia | D14: Quincena | E14: F2 | F14: Bls | G14: 5067 | H14: 5504 | I14: 98.4732 | J14: 95.587 | N14: 774.6899 | O14: 1024299.9 | P14: 192056.22 | Q14: 153644.98 | R14: 0.15 | S14: 38411.24 | T14: 0.0375
A15: - | B15: II-GAS | C15: Servicios | D15: Mes | E15: F1 | F15: MM BTU | G15: 26200.45 | H15: 11116.5 | I15: 2.6775 | J15: 2.6775 | N15: 826.0266 | O15: 99090.103 | P15: 18579.39 | Q15: 14863.52 | R15: 0.15 | S15: 3715.87 | T15: 0.0375
A16: - | B16: III | C16: Licencia | D16: Quincena | E16: F2 | F16: Bls | G16: 8077 | H16: 12169 | I16: 98.0823 | J16: 95.8076 | N16: 550.6826 | O16: 1957542.7 | P16: 367039.26 | Q16: 293631.41 | R16: 0.15 | S16: 73407.85 | T16: 0.0375
A17: - | B17: IV | C17: Licencia | D17: Quincena | E17: F2 | F17: Bls | G17: 38066 | H17: 40315 | I17: 98.0823 | J17: 95.8076 | N17: 1423.3768 | O17: 7594660.8 | P17: 1423998.9 | Q17: 1139199.1 | R17: 0.15 | S17: 284799.78 | T17: 0.0375
A18: - | B18: III (T) | C18: Licencia | D18: Quincena | E18: F2 | F18: Bls | O18: 0 | P18: 0 | Q18: 0 | R18: 0.15 | S18: 0 | T18: 0.0375
A19: - | B19: IV (T) | C19: Licencia | D19: Quincena | E19: F2 | F19: Bls | O19: 0 | P19: 0 | Q19: 0 | R19: 0.15 | S19: 0 | T19: 0.0375
A20: - | B20: IV-GAS | C20: Licencia | D20: Quincena | E20: F2 | F20: Bls | G20: 57459.4 | H20: 62963.65 | I20: 3.7058 | J20: 3.7058 | O20: 446263.73 | P20: 83674.45 | Q20: 66939.56 | R20: 0.15 | S20: 16734.89 | T20: 0.0375
A21: - | B21: V | C21: Servicios | D21: Mes | E21: F1 | F21: Bls | H21: 3542 | J21: 96.8908 | N21: 653.3533 | O21: 342533.86 | P21: 64225.1 | Q21: 51380.08 | R21: 0.15 | S21: 12845.02 | T21: 0.0375
A22: - | B22: VII/VI | C22: Licencia | D22: Quincena | E22: F2 | F22: Bls | G22: 49341 | H22: 59637 | I22: 97.5323 | J22: 95.2576 | N22: 3966.7848 | O22: 10489252 | P22: 1966734.7 | Q22: 1573387.8 | R22: 0.15 | S22: 393346.95 | T22: 0.0375
A23: - | B23: VII | C23: Servicios | D23: Mes | E23: F1 | F23: Bls | O23: 0 | P23: 0 | Q23: 0 | R23: 0.15 | S23: 0 | T23: 0.0375
A24: - | B24: VII/VI-GAS | C24: Licencia | D24: Quincena | E24: F2 | F24: MM BTU | G24: 71811.73 | H24: 46496.32 | I24: 2.8001 | J24: 2.8001 | N24: 928.6946 | O24: 330345.69 | P24: 61939.82 | Q24: 49551.85 | R24: 0.15 | S24: 12387.96 | T24: 0.0375
A25: - | B25: IX | C25: Licencia | D25: Quincena | E25: F2 | F25: Bls | G25: 1888 | H25: 2766 | I25: 98.0823 | J25: 95.8076 | N25: 322.0089 | O25: 449861.19 | P25: 84348.97 | Q25: 67479.18 | R25: 0.15 | S25: 16869.79 | T25: 0.0375
A26: - | B26: X | C26: Licencia | D26: Quincena | E26: F2 | F26: Bls | G26: 166915 | H26: 179077 | I26: 98.0823 | J26: 95.8076 | N26: 4965.4768 | O26: 33523379 | P26: 6285633.6 | Q26: 5028506.9 | R26: 0.15 | S26: 1257126.7 | T26: 0.0375
A27: - | B27: X-GAS | C27: Licencia | D27: Mes | E27: F2 | F27: MM BTU | G27: 251626.67 | H27: 274037.4 | I27: 2.4953 | J27: 2.4953 | N27: 980.0287 | O27: 1310709.5 | P27: 245758.04 | Q27: 196606.43 | R27: 0.15 | S27: 49151.61 | T27: 0.0375
A28: - | B28: XIV | C28: Licencia | D28: Mes | E28: F2 | F28: Bls | O28: 0 | P28: 0 | Q28: 0 | R28: 0.15 | S28: 0 | T28: 0.0375
A29: - | B29: XV | C29: Licencia | D29: Quincena | E29: F2 | F29: Bls | G29: 373 | H29: 554 | I29: 97.81 | J29: 96.8509 | N29: 350.0104 | O29: 89788.52 | P29: 16835.35 | Q29: 13468.28 | R29: 0.15 | S29: 3367.07 | T29: 0.0375
A30: - | B30: XIII Crudo | C30: Licencia | D30: Quincena | E30: F2 | F30: Bls | G30: 24581 | H30: 25600 | I30: 95.6923 | J30: 93.4176 | N30: 3336.7639 | O30: 4740366.2 | P30: 888818.67 | Q30: 711054.93 | R30: 0.15 | S30: 177763.73 | T30: 0.0375
A31: - | B31: XIII COND | C31: Licencia | D31: Quincena | E31: F2 | F31: Bls | O31: 0 | P31: 0 | Q31: 0 | R31: 0.15 | S31: 0 | T31: 0.0375
A32: - | B32: XIII Gas - A | C32: Licencia | D32: Quincena | E32: F2 | F32: MM BTU | G32: 170942.27 | H32: 178616.2 | I32: 1.61 | J32: 1.61 | N32: 1386.0396 | O32: 561403.09 | P32: 105263.08 | Q32: 84210.46 | R32: 0.15 | S32: 21052.62 | T32: 0.0375
A33: - | B33: XIII Gas - B | C33: Licencia | D33: Quincena | E33: F2 | F33: MM BTU | G33: 85251.41 | H33: 28341.96 | I33: 3.7766 | J33: 4.187 | O33: 440628.27 | P33: 82617.8 | Q33: 66094.24 | R33: 0.15 | S33: 16523.56 | T33: 0.0375
A34: - | B34: XIII Llantera | C34: Licencia | D34: Quincena | E34: F2 | F34: MM BTU | O34: 0 | P34: 0 | Q34: 0 | R34: 0.15 | S34: 0 | T34: 0.0375
A35: - | B35: XIII Gas Expectativa | C35: Licencia | D35: Quincena | E35: F2 | F35: MM BTU | O35: 0 | P35: 0 | Q35: 0 | R35: 0.15 | S35: 0 | T35: 0.0375
A36: - | B36: XIII Gas Paita | C36: Licencia | D36: Quincena | E36: F2 | F36: MM BTU | G36: 16984 | H36: 20511.03 | I36: 3.6523 | J36: 3.3908 | O36: 131579.46 | P36: 24671.15 | Q36: 19736.92 | R36: 0.15 | S36: 4934.23 | T36: 0.0375
A37: - | B37: XIII Gas Efe-01 | C37: Licencia | D37: Quincena | E37: F2 | F37: MM BTU | G37: 19564.149 | H37: 80153.231 | I37: 3.4126 | J37: 3.5 | O37: 347300.93 | P37: 65118.92 | Q37: 52095.14 | R37: 0.15 | S37: 13023.78 | T37: 0.0375
A38: - | B38: XIII Gas Efe-02 | C38: Licencia | D38: Quincena | E38: F2 | F38: MM BTU | G38: 1684.0881 | H38: 3465.4068 | I38: 3 | J38: 3 | O38: 15448.48 | P38: 2896.59 | Q38: 2317.27 | R38: 0.15 | S38: 579.32 | T38: 0.0375
A39: - | B39: Z-2B | C39: Servicios | D39: Mes | E39: F1 | F39: Bls | H39: 160495 | J39: 97.7409 | N39: 1073.3663 | O39: 15685852 | P39: 2941097.3 | Q39: 2352877.9 | R39: 0.15 | S39: 588219.46 | T39: 0.0375
A40: - | B40: Z-2B GAS | C40: Servicios | D40: Mes | E40: F1 | F40: MM BTU | H40: 444145.65 | J40: 8.7366 | N40: 942.6941 | O40: 3879380.2 | P40: 727383.79 | Q40: 581907.03 | R40: 0.15 | S40: 145476.76 | T40: 0.0375
A41: - | B41: XX | C41: Licencia | D41: Quincena | E41: F2 | F41: Bls | G41: 147 | H41: 188 | I41: 98.0823 | J41: 95.8076 | N41: 205.3387 | O41: 32224.591 | P41: 6042.11 | Q41: 1208.42 | R41: 0.0375 | S41: 4833.69 | T41: 0.15
...

Sheet Set
A1: Período de Cálculo: | E1: 44805 | F1: 3.985
A2: PERUPETRO S.A.
A3: DETERMINACION DEL CANON, SOBRECANON y PARTICIPACION (US$)
A4: Correspondiente a Setiembre 2022
A5: Tipo de Cambio= 3.985
A7: Localidad | C7: Modalidad de Contrato | D7: Calculo del Canon | F7: Volumen Producción / Venta | I7: Canasta o Valor Venta (US$/Unidad) | K7: Deducción de Gastos para determinación de valor de producción en Punto de Fiscalización (US$) | O7: Valor de la Producción (US$) | P7: Canon y Sobrecanon / Participación (US$)
A8: - Lote | D8: Período | E8: Fórmula | F8: Unidades | G8: 1ra. Q | H8: 2da. Q / Mes | I8: 1ra. Q | J8: 2da. Q / Mes | K8: Flete Marítimo | L8: Comercialización | M8: Oleoducto | N8: Fiscalización | P8: Total | Q8: Localidad 1 | S8: Localidad 2
A9: Piura / Tumbes | Q9: Piura | S9: Tumbes
A10: - | B10: I | C10: Servicios | D10: Mes | E10: F1 | F10: Bls | O10: 0 | P10: 0 | Q10: 0 | R10: 0.15 | S10: 0 | T10: 0.0375
A11: - | B11: I GAS | C11: Servicios | D11: Mes | E11: F1 | F11: MM BTU | O11: 0 | P11: 0 | Q11: 0 | R11: 0.15 | S11: 0 | T11: 0.0375
A12: - | B12: I (T) | C12: Licencia | D12: Quincena | E12: F1 | F12: Bls | G12: 5639 | H12: 9694 | I12: 90.7476 | J12: 86.7098 | N12: 288.4538 | O12: 1352002.1 | P12: 253500.39 | Q12: 202800.31 | R12: 0.15 | S12: 50700.08 | T12: 0.0375
A13: - | B13: I GAS (T) | C13: Licencia | D13: Quincena | E13: F1 | F13: MM BTU | G13: 50554.3 | H13: 50637.98 | I13: 3 | J13: 3 | N13: 811.2776 | O13: 302765.56 | P13: 56768.54 | Q13: 45414.83 | R13: 0.15 | S13: 11353.71 | T13: 0.0375
