Workbook
Name tc: Set!$N$1
Name tc: Ago!$N$1

Sheet Dic (2)
A1: Período de Cálculo: | E1: 44531 | U1: Días en el mes | W1: 31
A2: PERUPETRO S.A.
A3: DETERMINACION DEL CANON, SOBRECANON y PARTICIPACION (US$)
A4: ="Correspondiente a "&TEXT(E1,"MMMMMMM YYYY") -> Correspondiente a Diciembre 2021
A5: ="Tipo de Cambio= "&TEXT(F1,"0.000") -> Tipo de Cambio= 0.000
A7: Localidad | C7: Modalidad de Contrato | D7: Calculo del Canon | F7: Volumen Producción / Venta | I7: Canasta o Valor Venta (US$/Unidad) | K7: Deducción de Gastos para determinación de valor de producción en Punto de Fiscalización (US$) | O7: Valor de la Producción (US$) | P7: Canon y Sobrecanon / Participación (US$) | U7: Resumen por Petróleo y Condensados | AA7: Resumen por Gas Natural | AG7: Control
A8: - Lote | D8: Período | E8: Fórmula | F8: Unidades | G8: 1ra. Q | H8: 2da. Q / Mes | I8: 1ra. Q | J8: 2da. Q / Mes | K8: Flete Marítimo | L8: Comercialización | M8: Oleoducto | N8: Fiscalización | P8: Total | Q8: Localidad 1 | S8: Localidad 2 | U8: Producción / Venta | X8: Valor Prod | Y8: Valor Canon | AA8: Producción / Venta | AD8: Valor Prod | AE8: Valor Canon | AG8: Total
A9: Piura / Tumbes | Q9: Piura | S9: Tumbes | U9: Bls/Mes | V9: V P (US$) | W9: Bls/Día | X9: US$/Bl | Y9: US$/Bl | Z9: US$ | AA9: MM BTU/Mes | AB9: V P (US$) | AC9: MM BTU/Día | AD9: US$/MM BTU | AE9: US$/MM BTU | AF9: US$ | AG9: Canon
A10: - | B10: I | C10: Servicios | D10: Mes | E10: F1 | F10: Bls | H10: 25833 | J10: 62.2551 | N10: 672.29 | O10: =ROUND(G10*I10,2)+ROUND(H10*J10,2)-K10-L10-M10-N10 -> 1607563.7 | P10: =ROUND(18.75%*O10,2) -> 301418.2 | Q10: =ROUND($O10*R10,2) -> 241134.56 | R10: 0.15 | S10: =ROUND($O10*T10,2) -> 60283.64 | T10: 0.0375 | U10: =IF($F10&"/Día"=W$9,SUM($G10:$H10),"") -> 25833 | V10: =IF(U10<>"",$O10,"") -> 1607563.7 | W10: =IF($F10&"/Día"=W$9,ROUND(U10/$W$1,1),"") -> 833.3 | X10: =IF(U10=0,0,IF($F10&"/Día"=W$9,ROUND(V10/U10,4),"")) -> 62.2291 | Y10: =IF(U10=0,0,IF($F10&"/Día"=W$9,ROUND(Z10/U10,4),"")) -> 11.668 | Z10: =IF(U10<>"",$P10,"") -> 301418.2 | AA10: =IF($F10&"/Día"=AC$9,SUM($G10:$H10),"") | AB10: =IF(AA10<>"",$O10,"") | AC10: =IF($F10&"/Día"=AC$9,ROUND(AA10/$W$1,1),"") | AD10: =IF(AA10=0,0,IF($F10&"/Día"=AC$9,ROUND(AB10/AA10,4),"")) | AE10: =IF(AA10=0,0,IF($F10&"/Día"=AC$9,ROUND(AF10/AA10,4),"")) | AF10: =IF(AA10<>"",$P10,"")
A11: - | B11: I GAS | C11: Servicios | D11: Mes | E11: F1 | F11: MM BTU | H11: 254280.4 | J11: 3.0812 | N11: 1882.44 | O11: =ROUND(G11*I11,2)+ROUND(H11*J11,2)-K11-L11-M11-N11 -> 781606.33 | P11: =ROUND(18.75%*O11,2) -> 146551.19 | Q11: =ROUND($O11*R11,2) -> 117240.95 | R11: 0.15 | S11: =ROUND($O11*T11,2) -> 29310.24 | T11: 0.0375 | U11: =IF($F11&"/Día"=W$9,SUM($G11:$H11),"") | V11: =IF(U11<>"",$O11,"") | W11: =IF($F11&"/Día"=W$9,ROUND(U11/$W$1,1),"") | X11: =IF(U11=0,0,IF($F11&"/Día"=W$9,ROUND(V11/U11,4),"")) | Y11: =IF(U11=0,0,IF($F11&"/Día"=W$9,ROUND(Z11/U11,4),"")) | Z11: =IF(U11<>"",$P11,"") | AA11: =IF($F11&"/Día"=AC$9,SUM($G11:$H11),"") -> 254280.4 | AB11: =IF(AA11<>"",$O11,"") -> 781606.33 | AC11: =IF($F11&"/Día"=AC$9,ROUND(AA11/$W$1,1),"") -> 8202.6 | AD11: =IF(AA11=0,0,IF($F11&"/Día"=AC$9,ROUND(AB11/AA11,4),"")) -> 3.0738 | AE11: =IF(AA11=0,0,IF($F11&"/Día"=AC$9,ROUND(AF11/AA11,4),"")) -> 0.5763 | AF11: =IF(AA11<>"",$P11,"") -> 146551.19
A12: - | B12: II | C12: Licencia | D12: Quincena | E12: F2 | F12: Bls | G12: 4603 | H12: 4743 | I12: 59.4397 | J12: 61.3637 | N12: 1735.69 | O12: =ROUND(G12*I12,2)+ROUND(H12*J12,2)-K12-L12-M12-N12 -> 562913.28 | P12: =ROUND(18.75%*O12,2) -> 105546.24 | Q12: =ROUND($O12*R12,2) -> 84436.99 | R12: 0.15 | S12: =ROUND($O12*T12,2) -> 21109.25 | T12: 0.0375 | U12: =IF($F12&"/Día"=W$9,SUM($G12:$H12),"") -> 9346 | V12: =IF(U12<>"",$O12,"") -> 562913.28 | W12: =IF($F12&"/Día"=W$9,ROUND(U12/$W$1,1),"") -> 301.5 | X12: =IF(U12=0,0,IF($F12&"/Día"=W$9,ROUND(V12/U12,4),"")) -> 60.2304 | Y12: =IF(U12=0,0,IF($F12&"/Día"=W$9,ROUND(Z12/U12,4),"")) -> 11.2932 | Z12: =IF(U12<>"",$P12,"") -> 105546.24 | AA12: =IF($F12&"/Día"=AC$9,SUM($G12:$H12),"") | AB12: =IF(AA12<>"",$O12,"") | AC12: =IF($F12&"/Día"=AC$9,ROUND(AA12/$W$1,1),"") | AD12: =IF(AA12=0,0,IF($F12&"/Día"=AC$9,ROUND(AB12/AA12,4),"")) | AE12: =IF(AA12=0,0,IF($F12&"/Día"=AC$9,ROUND(AF12/AA12,4),"")) | AF12: =IF(AA12<>"",$P12,"")
A13: - | B13: II-GAS | C13: Servicios | D13: Mes | E13: F1 | F13: MM BTU | G13: 46670.52 | H13: 44626.41 | I13: 2.55 | J13: 2.55 | N13: 1853.41 | O13: =ROUND(G13*I13,2)+ROUND(H13*J13,2)-K13-L13-M13-N13 -> 230953.77 | P13: =ROUND(18.75%*O13,2) -> 43303.83 | Q13: =ROUND($P13*R13/(R13+T13),2) -> 34643.06 | R13: 0.15 | S13: =P13-Q13 -> 8660.77 | T13: 0.0375 | U13: =IF($F13&"/Día"=W$9,SUM($G13:$H13),"") | V13: =IF(U13<>"",$O13,"") | W13: =IF($F13&"/Día"=W$9,ROUND(U13/$W$1,1),"") | X13: =IF(U13=0,0,IF($F13&"/Día"=W$9,ROUND(V13/U13,4),"")) | Y13: =IF(U13=0,0,IF($F13&"/Día"=W$9,ROUND(Z13/U13,4),"")) | Z13: =IF(U13<>"",$P13,"") | AA13: =IF($F13&"/Día"=AC$9,SUM($G13:$H13),"") -> 91296.93 | AB13: =IF(AA13<>"",$O13,"") -> 230953.77 | AC13: =IF($F13&"/Día"=AC$9,ROUND(AA13/$W$1,1),"") -> 2945.1 | AD13: =IF(AA13=0,0,IF($F13&"/Día"=AC$9,ROUND(AB13/AA13,4),"")) -> 2.5297 | AE13: =IF(AA13=0,0,IF($F13&"/Día"=AC$9,ROUND(AF13/AA13,4),"")) -> 0.4743 | AF13: =IF(AA13<>"",$P13,"") -> 43303.83
A14: - | B14: III | C14: Licencia | D14: Quincena | E14: F2 | F14: Bls | G14: 12465 | H14: 13437 | I14: 61.5768 | J14: 63.1877 | N14: 1236.55 | O14: =ROUND(G14*I14,2)+ROUND(H14*J14,2)-K14-L14-M14-N14 -> 1615371.4 | P14: =ROUND(18.75%*O14,2) -> 302882.13 | Q14: =ROUND($O14*R14,2) -> 242305.71 | R14: 0.15 | S14: =ROUND($O14*T14,2) -> 60576.43 | T14: 0.0375 | U14: =IF($F14&"/Día"=W$9,SUM($G14:$H14),"") -> 25902 | V14: =IF(U14<>"",$O14,"") -> 1615371.4 | W14: =IF($F14&"/Día"=W$9,ROUND(U14/$W$1,1),"") -> 835.5 | X14: =IF(U14=0,0,IF($F14&"/Día"=W$9,ROUND(V14/U14,4),"")) -> 62.3647 | Y14: =IF(U14=0,0,IF($F14&"/Día"=W$9,ROUND(Z14/U14,4),"")) -> 11.6934 | Z14: =IF(U14<>"",$P14,"") -> 302882.13 | AA14: =IF($F14&"/Día"=AC$9,SUM($G14:$H14),"") | AB14: =IF(AA14<>"",$O14,"") | AC14: =IF($F14&"/Día"=AC$9,ROUND(AA14/$W$1,1),"") | AD14: =IF(AA14=0,0,IF($F14&"/Día"=AC$9,ROUND(AB14/AA14,4),"")) | AE14: =IF(AA14=0,0,IF($F14&"/Día"=AC$9,ROUND(AF14/AA14,4),"")) | AF14: =IF(AA14<>"",$P14,"")
A15: - | B15: IV | C15: Licencia | D15: Quincena | E15: F2 | F15: Bls | G15: 17654 | H15: 19218 | I15: 61.5768 | J15: 63.1877 | N15: 4217.85 | O15: =ROUND(G15*I15,2)+ROUND(H15*J15,2)-K15-L15-M15-N15 -> 2297200.2 | P15: =ROUND(18.75%*O15,2) -> 430725.04 | Q15: =ROUND($O15*R15,2) -> 344580.03 | R15: 0.15 | S15: =ROUND($O15*T15,2) -> 86145.01 | T15: 0.0375 | U15: =IF($F15&"/Día"=W$9,SUM($G15:$H15),"") -> 36872 | V15: =IF(U15<>"",$O15,"") -> 2297200.2 | W15: =IF($F15&"/Día"=W$9,ROUND(U15/$W$1,1),"") -> 1189.4 | X15: =IF(U15=0,0,IF($F15&"/Día"=W$9,ROUND(V15/U15,4),"")) -> 62.302 | Y15: =IF(U15=0,0,IF($F15&"/Día"=W$9,ROUND(Z15/U15,4),"")) -> 11.6816 | Z15: =IF(U15<>"",$P15,"") -> 430725.04 | AA15: =IF($F15&"/Día"=AC$9,SUM($G15:$H15),"") | AB15: =IF(AA15<>"",$O15,"") | AC15: =IF($F15&"/Día"=AC$9,ROUND(AA15/$W$1,1),"") | AD15: =IF(AA15=0,0,IF($F15&"/Día"=AC$9,ROUND(AB15/AA15,4),"")) | AE15: =IF(AA15=0,0,IF($F15&"/Día"=AC$9,ROUND(AF15/AA15,4),"")) | AF15: =IF(AA15<>"",$P15,"")
A16: - | B16: V | C16: Servicios | D16: Mes | E16: F1 | F16: Bls | H16: 2501 | J16: 62.2551 | N16: 1463.01 | O16: =ROUND(G16*I16,2)+ROUND(H16*J16,2)-K16-L16-M16-N16 -> 154237 | P16: =ROUND(18.75%*O16,2) -> 28919.44 | Q16: =ROUND($O16*R16,2) -> 23135.55 | R16: 0.15 | S16: =ROUND($O16*T16,2) -> 5783.89 | T16: 0.0375 | U16: =IF($F16&"/Día"=W$9,SUM($G16:$H16),"") -> 2501 | V16: =IF(U16<>"",$O16,"") -> 154237 | W16: =IF($F16&"/Día"=W$9,ROUND(U16/$W$1,1),"") -> 80.7 | X16: =IF(U16=0,0,IF($F16&"/Día"=W$9,ROUND(V16/U16,4),"")) -> 61.6701 | Y16: =IF(U16=0,0,IF($F16&"/Día"=W$9,ROUND(Z16/U16,4),"")) -> 11.5632 | Z16: =IF(U16<>"",$P16,"") -> 28919.44 | AA16: =IF($F16&"/Día"=AC$9,SUM($G16:$H16),"") | AB16: =IF(AA16<>"",$O16,"") | AC16: =IF($F16&"/Día"=AC$9,ROUND(AA16/$W$1,1),"") | AD16: =IF(AA16=0,0,IF($F16&"/Día"=AC$9,ROUND(AB16/AA16,4),"")) | AE16: =IF(AA16=0,0,IF($F16&"/Día"=AC$9,ROUND(AF16/AA16,4),"")) | AF16: =IF(AA16<>"",$P16,"")
A17: - | B17: VII/VI | C17: Licencia | D17: Quincena | E17: F2 | F17: Bls | G17: 46539 | H17: 63257 | I17: 61.0268 | J17: 62.6377 | N17: 2185.19 | O17: =ROUND(G17*I17,2)+ROUND(H17*J17,2)-K17-L17-M17-N17 -> 6800214 | P17: =ROUND(18.75%*O17,2) -> 1275040.1 | Q17: =ROUND($O17*R17,2) -> 1020032.1 | R17: 0.15 | S17: =ROUND($O17*T17,2) -> 255008.03 | T17: 0.0375 | U17: =IF($F17&"/Día"=W$9,SUM($G17:$H17),"") -> 109796 | V17: =IF(U17<>"",$O17,"") -> 6800214 | W17: =IF($F17&"/Día"=W$9,ROUND(U17/$W$1,1),"") -> 3541.8 | X17: =IF(U17=0,0,IF($F17&"/Día"=W$9,ROUND(V17/U17,4),"")) -> 61.935 | Y17: =IF(U17=0,0,IF($F17&"/Día"=W$9,ROUND(Z17/U17,4),"")) -> 11.6128 | Z17: =IF(U17<>"",$P17,"") -> 1275040.1 | AA17: =IF($F17&"/Día"=AC$9,SUM($G17:$H17),"") | AB17: =IF(AA17<>"",$O17,"") | AC17: =IF($F17&"/Día"=AC$9,ROUND(AA17/$W$1,1),"") | AD17: =IF(AA17=0,0,IF($F17&"/Día"=AC$9,ROUND(AB17/AA17,4),"")) | AE17: =IF(AA17=0,0,IF($F17&"/Día"=AC$9,ROUND(AF17/AA17,4),"")) | AF17: =IF(AA17<>"",$P17,"")
A18: - | B18: VII | C18: Servicios | D18: Mes | E18: F1 | F18: Bls | O18: =ROUND(G18*I18,2)+ROUND(H18*J18,2)-K18-L18-M18-N18 -> 0 | P18: =ROUND(18.75%*O18,2) -> 0 | Q18: =ROUND($O18*R18,2) -> 0 | R18: 0.15 | S18: =ROUND($O18*T18,2) -> 0 | T18: 0.0375 | U18: =IF($F18&"/Día"=W$9,SUM($G18:$H18),"") -> 0 | V18: =IF(U18<>"",$O18,"") -> 0 | W18: =IF($F18&"/Día"=W$9,ROUND(U18/$W$1,1),"") -> 0 | X18: =IF(U18=0,0,IF($F18&"/Día"=W$9,ROUND(V18/U18,4),"")) -> 0 | Y18: =IF(U18=0,0,IF($F18&"/Día"=W$9,ROUND(Z18/U18,4),"")) -> 0 | Z18: =IF(U18<>"",$P18,"") -> 0 | AA18: =IF($F18&"/Día"=AC$9,SUM($G18:$H18),"") | AB18: =IF(AA18<>"",$O18,"") | AC18: =IF($F18&"/Día"=AC$9,ROUND(AA18/$W$1,1),"") | AD18: =IF(AA18=0,0,IF($F18&"/Día"=AC$9,ROUND(AB18/AA18,4),"")) | AE18: =IF(AA18=0,0,IF($F18&"/Día"=AC$9,ROUND(AF18/AA18,4),"")) | AF18: =IF(AA18<>"",$P18,"")
A19: - | B19: VII/VI-GAS | C19: Licencia | D19: Quincena | E19: F2 | F19: MM BTU | G19: 54248.37 | H19: 59860.6 | I19: 1.8097 | J19: 2.1734 | N19: 2086.61 | O19: =ROUND(G19*I19,2)+ROUND(H19*J19,2)-K19-L19-M19-N19 -> 226187.7 | P19: =ROUND(18.75%*O19,2) -> 42410.19 | Q19: =ROUND($O19*R19,2) -> 33928.16 | R19: 0.15 | S19: =ROUND($O19*T19,2) -> 8482.04 | T19: 0.0375 | U19: =IF($F19&"/Día"=W$9,SUM($G19:$H19),"") | V19: =IF(U19<>"",$O19,"") | W19: =IF($F19&"/Día"=W$9,ROUND(U19/$W$1,1),"") | X19: =IF(U19=0,0,IF($F19&"/Día"=W$9,ROUND(V19/U19,4),"")) | Y19: =IF(U19=0,0,IF($F19&"/Día"=W$9,ROUND(Z19/U19,4),"")) | Z19: =IF(U19<>"",$P19,"") | AA19: =IF($F19&"/Día"=AC$9,SUM($G19:$H19),"") -> 114108.97 | AB19: =IF(AA19<>"",$O19,"") -> 226187.7 | AC19: =IF($F19&"/Día"=AC$9,ROUND(AA19/$W$1,1),"") -> 3680.9 | AD19: =IF(AA19=0,0,IF($F19&"/Día"=AC$9,ROUND(AB19/AA19,4),"")) -> 1.9822 | AE19: =IF(AA19=0,0,IF($F19&"/Día"=AC$9,ROUND(AF19/AA19,4),"")) -> 0.3717 | AF19: =IF(AA19<>"",$P19,"") -> 42410.19
A20: - | B20: IX | C20: Licencia | D20: Quincena | E20: F2 | F20: Bls | G20: 1870 | H20: 3543 | I20: 61.5768 | J20: 63.1877 | N20: 725.6 | O20: =ROUND(G20*I20,2)+ROUND(H20*J20,2)-K20-L20-M20-N20 -> 338297.04 | P20: =ROUND(18.75%*O20,2) -> 63430.7 | Q20: =ROUND($O20*R20,2) -> 50744.56 | R20: 0.15 | S20: =ROUND($O20*T20,2) -> 12686.14 | T20: 0.0375 | U20: =IF($F20&"/Día"=W$9,SUM($G20:$H20),"") -> 5413 | V20: =IF(U20<>"",$O20,"") -> 338297.04 | W20: =IF($F20&"/Día"=W$9,ROUND(U20/$W$1,1),"") -> 174.6 | X20: =IF(U20=0,0,IF($F20&"/Día"=W$9,ROUND(V20/U20,4),"")) -> 62.4971 | Y20: =IF(U20=0,0,IF($F20&"/Día"=W$9,ROUND(Z20/U20,4),"")) -> 11.7182 | Z20: =IF(U20<>"",$P20,"") -> 63430.7 | AA20: =IF($F20&"/Día"=AC$9,SUM($G20:$H20),"") | AB20: =IF(AA20<>"",$O20,"") | AC20: =IF($F20&"/Día"=AC$9,ROUND(AA20/$W$1,1),"") | AD20: =IF(AA20=0,0,IF($F20&"/Día"=AC$9,ROUND(AB20/AA20,4),"")) | AE20: =IF(AA20=0,0,IF($F20&"/Día"=AC$9,ROUND(AF20/AA20,4),"")) | AF20: =IF(AA20<>"",$P20,"")
A21: - | B21: X | C21: Licencia | D21: Quincena | E21: F2 | F21: Bls | G21: 195510 | H21: 209490 | I21: 61.5768 | J21: 63.1877 | N21: 4262.61 | O21: =ROUND(G21*I21,2)+ROUND(H21*J21,2)-K21-L21-M21-N21 -> 25271809 | P21: =ROUND(18.75%*O21,2) -> 4738464.2 | Q21: =ROUND($O21*R21,2) -> 3790771.3 | R21: 0.15 | S21: =ROUND($O21*T21,2) -> 947692.83 | T21: 0.0375 | U21: =IF($F21&"/Día"=W$9,SUM($G21:$H21),"") -> 405000 | V21: =IF(U21<>"",$O21,"") -> 25271809 | W21: =IF($F21&"/Día"=W$9,ROUND(U21/$W$1,1),"") -> 13064.5 | X21: =IF(U21=0,0,IF($F21&"/Día"=W$9,ROUND(V21/U21,4),"")) -> 62.3995 | Y21: =IF(U21=0,0,IF($F21&"/Día"=W$9,ROUND(Z21/U21,4),"")) -> 11.6999 | Z21: =IF(U21<>"",$P21,"") -> 4738464.2 | AA21: =IF($F21&"/Día"=AC$9,SUM($G21:$H21),"") | AB21: =IF(AA21<>"",$O21,"") | AC21: =IF($F21&"/Día"=AC$9,ROUND(AA21/$W$1,1),"") | AD21: =IF(AA21=0,0,IF($F21&"/Día"=AC$9,ROUND(AB21/AA21,4),"")) | AE21: =IF(AA21=0,0,IF($F21&"/Día"=AC$9,ROUND(AF21/AA21,4),"")) | AF21: =IF(AA21<>"",$P21,"")
A22: - | B22: X-GAS | C22: Licencia | D22: Mes | E22: F2 | F22: MM BTU | G22: 253486.59 | H22: 270429.23 | I22: 1.9713 | J22: 1.9713 | N22: 2198.25 | O22: =ROUND(G22*I22,2)+ROUND(H22*J22,2)-K22-L22-M22-N22 -> 1030597 | P22: =ROUND(18.75%*O22,2) -> 193236.94 | Q22: =ROUND($O22*R22,2) -> 154589.55 | R22: 0.15 | S22: =ROUND($O22*T22,2) -> 38647.39 | T22: 0.0375 | U22: =IF($F22&"/Día"=W$9,SUM($G22:$H22),"") | V22: =IF(U22<>"",$O22,"") | W22: =IF($F22&"/Día"=W$9,ROUND(U22/$W$1,1),"") | X22: =IF(U22=0,0,IF($F22&"/Día"=W$9,ROUND(V22/U22,4),"")) | Y22: =IF(U22=0,0,IF($F22&"/Día"=W$9,ROUND(Z22/U22,4),"")) | Z22: =IF(U22<>"",$P22,"") | AA22: =IF($F22&"/Día"=AC$9,SUM($G22:$H22),"") -> 523915.82 | AB22: =IF(AA22<>"",$O22,"") -> 1030597 | AC22: =IF($F22&"/Día"=AC$9,ROUND(AA22/$W$1,1),"") -> 16900.5 | AD22: =IF(AA22=0,0,IF($F22&"/Día"=AC$9,ROUND(AB22/AA22,4),"")) -> 1.9671 | AE22: =IF(AA22=0,0,IF($F22&"/Día"=AC$9,ROUND(AF22/AA22,4),"")) -> 0.3688 | AF22: =IF(AA22<>"",$P22,"") -> 193236.94
A23: - | B23: XIV | C23: Licencia | D23: Mes | E23: F2 | F23: Bls | O23: =ROUND(G23*I23,2)+ROUND(H23*J23,2)-K23-L23-M23-N23 -> 0 | P23: =ROUND(18.75%*O23,2) -> 0 | Q23: =ROUND($O23*R23,2) -> 0 | R23: 0.15 | S23: =ROUND($O23*T23,2) -> 0 | T23: 0.0375 | U23: =IF($F23&"/Día"=W$9,SUM($G23:$H23),"") -> 0 | V23: =IF(U23<>"",$O23,"") -> 0 | W23: =IF($F23&"/Día"=W$9,ROUND(U23/$W$1,1),"") -> 0 | X23: =IF(U23=0,0,IF($F23&"/Día"=W$9,ROUND(V23/U23,4),"")) -> 0 | Y23: =IF(U23=0,0,IF($F23&"/Día"=W$9,ROUND(Z23/U23,4),"")) -> 0 | Z23: =IF(U23<>"",$P23,"") -> 0 | AA23: =IF($F23&"/Día"=AC$9,SUM($G23:$H23),"") | AB23: =IF(AA23<>"",$O23,"") | AC23: =IF($F23&"/Día"=AC$9,ROUND(AA23/$W$1,1),"") | AD23: =IF(AA23=0,0,IF($F23&"/Día"=AC$9,ROUND(AB23/AA23,4),"")) | AE23: =IF(AA23=0,0,IF($F23&"/Día"=AC$9,ROUND(AF23/AA23,4),"")) | AF23: =IF(AA23<>"",$P23,"")
A24: - | B24: XV | C24: Licencia | D24: Quincena | E24: F2 | F24: Bls | G24: 542 | H24: 479 | I24: 61.4585 | J24: 63.27 | N24: 789.01 | O24: =ROUND(G24*I24,2)+ROUND(H24*J24,2)-K24-L24-M24-N24 -> 62827.83 | P24: =ROUND(18.75%*O24,2) -> 11780.22 | Q24: =ROUND($O24*R24,2) -> 9424.17 | R24: 0.15 | S24: =ROUND($O24*T24,2) -> 2356.04 | T24: 0.0375 | U24: =IF($F24&"/Día"=W$9,SUM($G24:$H24),"") -> 1021 | V24: =IF(U24<>"",$O24,"") -> 62827.83 | W24: =IF($F24&"/Día"=W$9,ROUND(U24/$W$1,1),"") -> 32.9 | X24: =IF(U24=0,0,IF($F24&"/Día"=W$9,ROUND(V24/U24,4),"")) -> 61.5356 | Y24: =IF(U24=0,0,IF($F24&"/Día"=W$9,ROUND(Z24/U24,4),"")) -> 11.5379 | Z24: =IF(U24<>"",$P24,"") -> 11780.22 | AA24: =IF($F24&"/Día"=AC$9,SUM($G24:$H24),"") | AB24: =IF(AA24<>"",$O24,"") | AC24: =IF($F24&"/Día"=AC$9,ROUND(AA24/$W$1,1),"") | AD24: =IF(AA24=0,0,IF($F24&"/Día"=AC$9,ROUND(AB24/AA24,4),"")) | AE24: =IF(AA24=0,0,IF($F24&"/Día"=AC$9,ROUND(AF24/AA24,4),"")) | AF24: =IF(AA24<>"",$P24,"")
A25: - | B25: XIII Crudo | C25: Licencia | D25: Quincena | E25: F2 | F25: Bls | G25: 29886 | H25: 39223 | I25: 61.5768 | J25: 63.1877 | N25: 1505.2 | O25: =ROUND(G25*I25,2)+ROUND(H25*J25,2)-K25-L25-M25-N25 -> 4317190.2 | P25: =ROUND(18.75%*O25,2) -> 809473.16 | Q25: =ROUND($O25*R25,2) -> 647578.53 | R25: 0.15 | S25: =ROUND($O25*T25,2) -> 161894.63 | T25: 0.0375 | U25: =IF($F25&"/Día"=W$9,SUM($G25:$H25),"") -> 69109 | V25: =IF(U25<>"",$O25,"") -> 4317190.2 | W25: =IF($F25&"/Día"=W$9,ROUND(U25/$W$1,1),"") -> 2229.3 | X25: =IF(U25=0,0,IF($F25&"/Día"=W$9,ROUND(V25/U25,4),"")) -> 62.4693 | Y25: =IF(U25=0,0,IF($F25&"/Día"=W$9,ROUND(Z25/U25,4),"")) -> 11.713 | Z25: =IF(U25<>"",$P25,"") -> 809473.16 | AA25: =IF($F25&"/Día"=AC$9,SUM($G25:$H25),"") | AB25: =IF(AA25<>"",$O25,"") | AC25: =IF($F25&"/Día"=AC$9,ROUND(AA25/$W$1,1),"") | AD25: =IF(AA25=0,0,IF($F25&"/Día"=AC$9,ROUND(AB25/AA25,4),"")) | AE25: =IF(AA25=0,0,IF($F25&"/Día"=AC$9,ROUND(AF25/AA25,4),"")) | AF25: =IF(AA25<>"",$P25,"")
A26: - | B26: XIII COND | C26: Licencia | D26: Quincena | E26: F2 | F26: Bls | O26: =ROUND(G26*I26,2)+ROUND(H26*J26,2)-K26-L26-M26-N26 -> 0 | P26: =ROUND(18.75%*O26,2) -> 0 | Q26: =ROUND($O26*R26,2) -> 0 | R26: 0.15 | S26: =ROUND($O26*T26,2) -> 0 | T26: 0.0375 | U26: =IF($F26&"/Día"=W$9,SUM($G26:$H26),"") -> 0 | V26: =IF(U26<>"",$O26,"") -> 0 | W26: =IF($F26&"/Día"=W$9,ROUND(U26/$W$1,1),"") -> 0 | X26: =IF(U26=0,0,IF($F26&"/Día"=W$9,ROUND(V26/U26,4),"")) -> 0 | Y26: =IF(U26=0,0,IF($F26&"/Día"=W$9,ROUND(Z26/U26,4),"")) -> 0 | Z26: =IF(U26<>"",$P26,"") -> 0 | AA26: =IF($F26&"/Día"=AC$9,SUM($G26:$H26),"") | AB26: =IF(AA26<>"",$O26,"") | AC26: =IF($F26&"/Día"=AC$9,ROUND(AA26/$W$1,1),"") | AD26: =IF(AA26=0,0,IF($F26&"/Día"=AC$9,ROUND(AB26/AA26,4),"")) | AE26: =IF(AA26=0,0,IF($F26&"/Día"=AC$9,ROUND(AF26/AA26,4),"")) | AF26: =IF(AA26<>"",$P26,"")
A27: - | B27: XIII Gas | C27: Licencia | D27: Quincena | E27: F2 | F27: MM BTU | G27: =66398.35+67054.56 -> 133452.91 | H27: =103068.34+75979.36 -> 179047.7 | I27: 2.7629297 | J27: 2.5652523 | N27: 3111.05 | O27: =ROUND(G27*I27,2)+ROUND(H27*J27,2)-K27-L27-M27-N27 -> 824912.48 | P27: =ROUND(18.75%*O27,2) -> 154671.09 | Q27: =ROUND($O27*R27,2) -> 123736.87 | R27: 0.15 | S27: =ROUND($O27*T27,2) -> 30934.22 | T27: 0.0375 | U27: =IF($F27&"/Día"=W$9,SUM($G27:$H27),"") | V27: =IF(U27<>"",$O27,"") | W27: =IF($F27&"/Día"=W$9,ROUND(U27/$W$1,1),"") | X27: =IF(U27=0,0,IF($F27&"/Día"=W$9,ROUND(V27/U27,4),"")) | Y27: =IF(U27=0,0,IF($F27&"/Día"=W$9,ROUND(Z27/U27,4),"")) | Z27: =IF(U27<>"",$P27,"") | AA27: =IF($F27&"/Día"=AC$9,SUM($G27:$H27),"") -> 312500.61 | AB27: =IF(AA27<>"",$O27,"") -> 824912.48 | AC27: =IF($F27&"/Día"=AC$9,ROUND(AA27/$W$1,1),"") -> 10080.7 | AD27: =IF(AA27=0,0,IF($F27&"/Día"=AC$9,ROUND(AB27/AA27,4),"")) -> 2.6397 | AE27: =IF(AA27=0,0,IF($F27&"/Día"=AC$9,ROUND(AF27/AA27,4),"")) -> 0.4949 | AF27: =IF(AA27<>"",$P27,"") -> 154671.09
A28: - | B28: Z-2B | C28: Servicios | D28: Mes | E28: F1 | F28: Bls | H28: =213883+40740 -> 254623 | J28: 59.458 | N28: 2405.36 | O28: =ROUND(G28*I28,2)+ROUND(H28*J28,2)-K28-L28-M28-N28 -> 15136969 | P28: =ROUND(18.75%*O28,2) -> 2838181.7 | Q28: =ROUND($O28*R28,2) -> 2270545.4 | R28: 0.15 | S28: =ROUND($O28*T28,2) -> 567636.34 | T28: 0.0375 | U28: =IF($F28&"/Día"=W$9,SUM($G28:$H28),"") -> 254623 | V28: =IF(U28<>"",$O28,"") -> 15136969 | W28: =IF($F28&"/Día"=W$9,ROUND(U28/$W$1,1),"") -> 8213.6 | X28: =IF(U28=0,0,IF($F28&"/Día"=W$9,ROUND(V28/U28,4),"")) -> 59.4486 | Y28: =IF(U28=0,0,IF($F28&"/Día"=W$9,ROUND(Z28/U28,4),"")) -> 11.1466 | Z28: =IF(U28<>"",$P28,"") -> 2838181.7 | AA28: =IF($F28&"/Día"=AC$9,SUM($G28:$H28),"") | AB28: =IF(AA28<>"",$O28,"") | AC28: =IF($F28&"/Día"=AC$9,ROUND(AA28/$W$1,1),"") | AD28: =IF(AA28=0,0,IF($F28&"/Día"=AC$9,ROUND(AB28/AA28,4),"")) | AE28: =IF(AA28=0,0,IF($F28&"/Día"=AC$9,ROUND(AF28/AA28,4),"")) | AF28: =IF(AA28<>"",$P28,"")
A29: - | B29: Z-2B GAS | C29: Servicios | D29: Mes | E29: F1 | F29: MM BTU | H29: =268464.02+1104.74+50031.27 -> 319600.03 | J29: 5.2256954 | N29: 2121.14 | O29: =ROUND(G29*I29,2)+ROUND(H29*J29,2)-K29-L29-M29-N29 -> 1668011.3 | P29: =ROUND(18.75%*O29,2) -> 312752.11 | Q29: =ROUND($O29*R29,2) -> 250201.69 | R29: 0.15 | S29: =ROUND($O29*T29,2) -> 62550.42 | T29: 0.0375 | U29: =IF($F29&"/Día"=W$9,SUM($G29:$H29),"") | V29: =IF(U29<>"",$O29,"") | W29: =IF($F29&"/Día"=W$9,ROUND(U29/$W$1,1),"") | X29: =IF(U29=0,0,IF($F29&"/Día"=W$9,ROUND(V29/U29,4),"")) | Y29: =IF(U29=0,0,IF($F29&"/Día"=W$9,ROUND(Z29/U29,4),"")) | Z29: =IF(U29<>"",$P29,"") | AA29: =IF($F29&"/Día"=AC$9,SUM($G29:$H29),"") -> 319600.03 | AB29: =IF(AA29<>"",$O29,"") -> 1668011.3 | AC29: =IF($F29&"/Día"=AC$9,ROUND(AA29/$W$1,1),"") -> 10309.7 | AD29: =IF(AA29=0,0,IF($F29&"/Día"=AC$9,ROUND(AB29/AA29,4),"")) -> 5.2191 | AE29: =IF(AA29=0,0,IF($F29&"/Día"=AC$9,ROUND(AF29/AA29,4),"")) -> 0.9786 | AF29: =IF(AA29<>"",$P29,"") -> 312752.11
A30: - | B30: XX | C30: Licencia | D30: Quincena | E30: F2 | F30: Bls | G30: 389 | H30: 344 | I30: 61.5768 | J30: 63.1877 | N30: 463.42 | O30: =ROUND(G30*I30,2)+ROUND(H30*J30,2)-K30-L30-M30-N30 -> 45226.53 | P30: =ROUND(18.75%*O30,2) -> 8479.97 | Q30: =ROUND($O30*R30,2) -> 1695.99 | R30: 0.0375 | S30: =ROUND($O30*T30,2) -> 6783.98 | T30: 0.15 | U30: =IF($F30&"/Día"=W$9,SUM($G30:$H30),"") -> 733 | V30: =IF(U30<>"",$O30,"") -> 45226.53 | W30: =IF($F30&"/Día"=W$9,ROUND(U30/$W$1,1),"") -> 23.6 | X30: =IF(U30=0,0,IF($F30&"/Día"=W$9,ROUND(V30/U30,4),"")) -> 61.7006 | Y30: =IF(U30=0,0,IF($F30&"/Día"=W$9,ROUND(Z30/U30,4),"")) -> 11.5689 | Z30: =IF(U30<>"",$P30,"") -> 8479.97 | AA30: =IF($F30&"/Día"=AC$9,SUM($G30:$H30),"") | AB30: =IF(AA30<>"",$O30,"") | AC30: =IF($F30&"/Día"=AC$9,ROUND(AA30/$W$1,1),"") | AD30: =IF(AA30=0,0,IF($F30&"/Día"=AC$9,ROUND(AB30/AA30,4),"")) | AE30: =IF(AA30=0,0,IF($F30&"/Día"=AC$9,ROUND(AF30/AA30,4),"")) | AF30: =IF(AA30<>"",$P30,"")
A31: - | B31: Z1 Crudo | C31: Licencia | D31: Quincena | E31: F2 | F31: Bls | H31: 55112 | J31: 63.1877 | N31: 1427.03 | O31: =ROUND(G31*I31,2)+ROUND(H31*J31,2)-K31-L31-M31-N31 -> 3480973.5 | P31: =ROUND(18.75%*O31,2) -> 652682.53 | Q31: =ROUND($O31*R31,2) -> 130536.51 | R31: 0.0375 | S31: =ROUND($O31*T31,2) -> 522146.02 | T31: 0.15 | U31: =IF($F31&"/Día"=W$9,SUM($G31:$H31),"") -> 55112 | V31: =IF(U31<>"",$O31,"") -> 3480973.5 | W31: =IF($F31&"/Día"=W$9,ROUND(U31/$W$1,1),"") -> 1777.8 | X31: =IF(U31=0,0,IF($F31&"/Día"=W$9,ROUND(V31/U31,4),"")) -> 63.1618 | Y31: =IF(U31=0,0,IF($F31&"/Día"=W$9,ROUND(Z31/U31,4),"")) -> 11.8428 | Z31: =IF(U31<>"",$P31,"") -> 652682.53 | AA31: =IF($F31&"/Día"=AC$9,SUM($G31:$H31),"") | AB31: =IF(AA31<>"",$O31,"") | AC31: =IF($F31&"/Día"=AC$9,ROUND(AA31/$W$1,1),"") | AD31: =IF(AA31=0,0,IF($F31&"/Día"=AC$9,ROUND(AB31/AA31,4),"")) | AE31: =IF(AA31=0,0,IF($F31&"/Día"=AC$9,ROUND(AF31/AA31,4),"")) | AF31: =IF(AA31<>"",$P31,"")
A32: - | B32: Z1 Gas | C32: Licencia | D32: Quincena | E32: F2 | F32: MM BTU | O32: =ROUND(G32*I32,2)+ROUND(H32*J32,2)-K32-L32-M32-N32 -> 0 | P32: =ROUND(18.75%*O32,2) -> 0 | Q32: =ROUND($O32*R32,2) -> 0 | R32: 0.0375 | S32: =ROUND($O32*T32,2) -> 0 | T32: 0.15 | U32: =IF($F32&"/Día"=W$9,SUM($G32:$H32),"") | V32: =IF(U32<>"",$O32,"") | W32: =IF($F32&"/Día"=W$9,ROUND(U32/$W$1,1),"") | X32: =IF(U32=0,0,IF($F32&"/Día"=W$9,ROUND(V32/U32,4),"")) | Y32: =IF(U32=0,0,IF($F32&"/Día"=W$9,ROUND(Z32/U32,4),"")) | Z32: =IF(U32<>"",$P32,"") | AA32: =IF($F32&"/Día"=AC$9,SUM($G32:$H32),"") -> 0 | AB32: =IF(AA32<>"",$O32,"") -> 0 | AC32: =IF($F32&"/Día"=AC$9,ROUND(AA32/$W$1,1),"") -> 0 | AD32: =IF(AA32=0,0,IF($F32&"/Día"=AC$9,ROUND(AB32/AA32,4),"")) -> 0 | AE32: =IF(AA32=0,0,IF($F32&"/Día"=AC$9,ROUND(AF32/AA32,4),"")) -> 0 | AF32: =IF(AA32<>"",$P32,"") -> 0
A33: - | B33: Z-2B - LGN | C33: Servicios | D33: Mes | E33: F1 | F33: Bls | H33: =23156+4411 -> 27567 | J33: 58.768 | N33: 2310.53 | O33: =ROUND(G33*I33,2)+ROUND(H33*J33,2)-K33-L33-M33-N33 -> 1617746.9 | P33: =ROUND(18.75%*O33,2) -> 303327.55 | Q33: =ROUND($O33*R33,2) -> 242662.04 | R33: 0.15 | S33: =ROUND($O33*T33,2) -> 60665.51 | T33: 0.0375 | U33: =IF($F33&"/Día"=W$9,SUM($G33:$H33),"") -> 27567 | V33: =IF(U33<>"",$O33,"") -> 1617746.9 | W33: =IF($F33&"/Día"=W$9,ROUND(U33/$W$1,1),"") -> 889.3 | X33: =IF(U33=0,0,IF($F33&"/Día"=W$9,ROUND(V33/U33,4),"")) -> 58.6842 | Y33: =IF(U33=0,0,IF($F33&"/Día"=W$9,ROUND(Z33/U33,4),"")) -> 11.0033 | Z33: =IF(U33<>"",$P33,"") -> 303327.55 | AA33: =IF($F33&"/Día"=AC$9,SUM($G33:$H33),"") | AB33: =IF(AA33<>"",$O33,"") | AC33: =IF($F33&"/Día"=AC$9,ROUND(AA33/$W$1,1),"") | AD33: =IF(AA33=0,0,IF($F33&"/Día"=AC$9,ROUND(AB33/AA33,4),"")) | AE33: =IF(AA33=0,0,IF($F33&"/Día"=AC$9,ROUND(AF33/AA33,4),"")) | AF33: =IF(AA33<>"",$P33,"")
A34: - | B34: Z-6 | C34: Licencia | D34: Quincena | E34: F2 | F34: MM BTU | O34: =ROUND(G34*I34,2)+ROUND(H34*J34,2)-K34-L34-M34-N34 -> 0 | P34: =ROUND(18.75%*O34,2) -> 0 | Q34: =ROUND($O34*R34,2) -> 0 | R34: 0.15 | S34: =ROUND($O34*T34,2) -> 0 | T34: 0.0375
A35: - | B35: Ajustes meses anteriores (1) | O35: =+O139 -> -23595.85 | P35: =+P139 -> -4424.22 | Q35: =+Q139 -> -3539.38 | S35: =+S139 -> -884.84 | U35: =IF($F35&"/Día"=W$9,SUM($G35:$H35),"") | V35: =IF(U35<>"",$O35,"") | W35: =IF($F35&"/Día"=W$9,ROUND(U35/$W$1,1),"") | X35: =IF(U35=0,0,IF($F35&"/Día"=W$9,ROUND(V35/U35,4),"")) | Y35: =IF(U35=0,0,IF($F35&"/Día"=W$9,ROUND(Z35/U35,4),"")) | Z35: =IF(U35<>"",$P35,"") | AA35: =IF($F35&"/Día"=AC$9,SUM($G35:$H35),"") | AB35: =IF(AA35<>"",$O35,"") | AC35: =IF($F35&"/Día"=AC$9,ROUND(AA35/$W$1,1),"") | AD35: =IF(AA35=0,0,IF($F35&"/Día"=AC$9,ROUND(AB35/AA35,4),"")) | AE35: =IF(AA35=0,0,IF($F35&"/Día"=AC$9,ROUND(AF35/AA35,4),"")) | AF35: =IF(AA35<>"",$P35,"")
B36: Subtotal | C36: =TEXT(A$9,)&" US$" -> Piura / Tumbes US$ | O36: =SUM(O10:O35) -> 68047212 | P36: =SUM(P10:P35) -> 12758852 | Q36: =SUM(Q10:Q35) -> 9810384.3 | S36: =SUM(S10:S35) -> 2948468 | U36: =SUM(U10:U35) -> 1028828 | V36: =SUM(V10:V35) -> 63308539 | W36: =SUM(W10:W35) -> 33187.8 | X36: =ROUND(V36/U36,4) -> 61.5346 | Y36: =ROUND(Z36/U36,4) -> 11.5377 | Z36: =SUM(Z10:Z35) -> 11870351 | AA36: =SUM(AA10:AA35) -> 1615702.8 | AB36: =SUM(AB10:AB35) -> 4762268.5 | AC36: =SUM(AC10:AC35) -> 52119.5 | AD36: =ROUND(AB36/AA36,4) -> 2.9475 | AE36: =ROUND(AF36/AA36,4) -> 0.5527 | AF36: =SUM(AF10:AF35) -> 892925.35 | AG36: =P36-Z36-AF36 -> -4424.22
C37: =TEXT(A$9,)&" S/." -> Piura / Tumbes S/. | P37: =ROUND($F$1*P36,2) -> 0 | Q37: =ROUND($F$1*Q36,2) -> 0 | S37: =ROUND($F$1*S36,2) -> 0
A38: Provincia Puerto Inca Huanuco | Q38: Puerto Inca
A39: - | B39: 31-D | C39: Licencia | D39: Quincena | E39: F2 | F39: Bls | G39: 2739 | I39: 61.5964 | N39: 1094.07 | O39: =ROUND(G39*I39,2)+ROUND(H39*J39,2)-K39-L39-M39-N39 -> 167618.47 | P39: =ROUND(15%*O39,2) -> 25142.77 | Q39: =ROUND($O39*R39,2) -> 25142.77 | R39: 0.15 | U39: =IF($F39&"/Día"=W$9,SUM($G39:$H39),"") -> 2739 | V39: =IF(U39<>"",$O39,"") -> 167618.47 | W39: =IF($F39&"/Día"=W$9,ROUND(U39/$W$1,1),"") -> 88.4 | X39: =IF(U39=0,0,IF($F39&"/Día"=W$9,ROUND(V39/U39,4),"")) -> 61.197 | Y39: =IF(U39=0,0,IF($F39&"/Día"=W$9,ROUND(Z39/U39,4),"")) -> 9.1795 | Z39: =IF(U39<>"",$P39,"") -> 25142.77 | AA39: =IF($F39&"/Día"=AC$9,SUM($G39:$H39),"") | AB39: =IF(AA39<>"",$O39,"") | AC39: =IF($F39&"/Día"=AC$9,ROUND(AA39/$W$1,1),"") | AD39: =IF(AA39=0,0,IF($F39&"/Día"=AC$9,ROUND(AB39/AA39,4),"")) | AE39: =IF(AA39=0,0,IF($F39&"/Día"=AC$9,ROUND(AF39/AA39,4),"")) | AF39: =IF(AA39<>"",$P39,"")
A40: - | B40: 131 | C40: Licencia | D40: Quincena | E40: F2 | F40: Bls | G40: 43803 | H40: 47994 | I40: 58.7224 | J40: 60.6102 | N40: 9288.93 | O40: =ROUND(G40*I40,2)+ROUND(H40*J40,2)-K40-L40-M40-N40 -> 5471854.3 | P40: =ROUND(15%*O40,2) -> 820778.15 | Q40: =ROUND($O40*R40,2) -> 820778.15 | R40: 0.15 | U40: =IF($F40&"/Día"=W$9,SUM($G40:$H40),"") -> 91797 | V40: =IF(U40<>"",$O40,"") -> 5471854.3 | W40: =IF($F40&"/Día"=W$9,ROUND(U40/$W$1,1),"") -> 2961.2 | X40: =IF(U40=0,0,IF($F40&"/Día"=W$9,ROUND(V40/U40,4),"")) -> 59.6082 | Y40: =IF(U40=0,0,IF($F40&"/Día"=W$9,ROUND(Z40/U40,4),"")) -> 8.9412 | Z40: =IF(U40<>"",$P40,"") -> 820778.15 | AA40: =IF($F40&"/Día"=AC$9,SUM($G40:$H40),"") | AB40: =IF(AA40<>"",$O40,"") | AC40: =IF($F40&"/Día"=AC$9,ROUND(AA40/$W$1,1),"") | AD40: =IF(AA40=0,0,IF($F40&"/Día"=AC$9,ROUND(AB40/AA40,4),"")) | AE40: =IF(AA40=0,0,IF($F40&"/Día"=AC$9,ROUND(AF40/AA40,4),"")) | AF40: =IF(AA40<>"",$P40,"")
A41: - | B41: Ajustes meses anteriores (2) | U41: =IF($F41&"/Día"=W$9,SUM($G41:$H41),"") | V41: =IF(U41<>"",$O41,"") | W41: =IF($F41&"/Día"=W$9,ROUND(U41/$W$1,1),"") | X41: =IF(U41=0,0,IF($F41&"/Día"=W$9,ROUND(V41/U41,4),"")) | Y41: =IF(U41=0,0,IF($F41&"/Día"=W$9,ROUND(Z41/U41,4),"")) | Z41: =IF(U41<>"",$P41,"") | AA41: =IF($F41&"/Día"=AC$9,SUM($G41:$H41),"") | AB41: =IF(AA41<>"",$O41,"") | AC41: =IF($F41&"/Día"=AC$9,ROUND(AA41/$W$1,1),"") | AD41: =IF(AA41=0,0,IF($F41&"/Día"=AC$9,ROUND(AB41/AA41,4),"")) | AE41: =IF(AA41=0,0,IF($F41&"/Día"=AC$9,ROUND(AF41/AA41,4),"")) | AF41: =IF(AA41<>"",$P41,"")
...

Sheet Feb (2)
A1: Período de Cálculo: | E1: 43132 | S1: , | U1: Días en el mes | W1: =DATE(YEAR(E1),MONTH(E1)+1,1)-DATE(YEAR(E1),MONTH(E1),1) -> 28
A2: PERUPETRO S.A.
A3: DETERMINACION DEL CANON, SOBRECANON y PARTICIPACION (US$)
A4: ="Correspondiente a "&TEXT(E1,"MMMMMMM YYYY") -> Correspondiente a febrero 2018
A5: ="Tipo de Cambio= "&TEXT(F1,"0.000") -> Tipo de Cambio= 0.000
A7: Localidad | C7: Modalidad de Contrato | D7: Calculo del Canon | F7: Volumen Producción / Venta | I7: Canasta o Valor Venta (US$/Unidad) | K7: Deducción de Gastos para determinación de valor de producción en Punto de Fiscalización (US$) | O7: Valor de la Producción (US$) | P7: Canon y Sobrecanon / Participación (US$) | U7: Resumen por Petróleo y Condensados | AA7: Resumen por Gas Natural | AG7: Control
A8: - Lote | D8: Período | E8: Fórmula | F8: Unidades | G8: 1ra. Q | H8: 2da. Q / Mes | I8: 1ra. Q | J8: 2da. Q / Mes | K8: Flete Marítimo | L8: Comercialización | M8: Oleoducto | N8: Fiscalización | P8: Total | Q8: Localidad 1 | S8: Localidad 2 | U8: Producción / Venta | X8: Valor Prod | Y8: Valor Canon | AA8: Producción / Venta | AD8: Valor Prod | AE8: Valor Canon | AG8: Total
A9: Piura / Tumbes | Q9: Piura | S9: Tumbes | U9: Bls/Mes | V9: V P (US$) | W9: Bls/Día | X9: US$/Bl | Y9: US$/Bl | Z9: US$ | AA9: MM BTU/Mes | AB9: V P (US$) | AC9: MM BTU/Día | AD9: US$/MM BTU | AE9: US$/MM BTU | AF9: US$ | AG9: Canon
A10: - | B10: I | C10: Servicios | D10: Mes | E10: F1 | F10: Bls | H10: 21037 | J10: 63.0188 | N10: 668.38 | O10: =ROUND(G10*I10,2)+ROUND(H10*J10,2)-K10-L10-M10-N10 -> 1325058.1 | P10: =ROUND(18.75%*O10,2) -> 248448.4 | Q10: =ROUND($O10*R10,2) -> 198758.72 | R10: 0.15 | S10: =ROUND($O10*T10,2) -> 49689.68 | T10: 0.0375 | U10: =IF($F10&"/Día"=W$9,SUM($G10:$H10),"") -> 21037 | V10: =IF(U10<>"",$O10,"") -> 1325058.1 | W10: =IF($F10&"/Día"=W$9,ROUND(U10/$W$1,1),"") -> 751.3 | X10: =IF(U10=0,0,IF($F10&"/Día"=W$9,ROUND(V10/U10,4),"")) -> 62.987 | Y10: =IF(U10=0,0,IF($F10&"/Día"=W$9,ROUND(Z10/U10,4),"")) -> 11.8101 | Z10: =IF(U10<>"",$P10,"") -> 248448.4 | AA10: =IF($F10&"/Día"=AC$9,SUM($G10:$H10),"") | AB10: =IF(AA10<>"",$O10,"") | AC10: =IF($F10&"/Día"=AC$9,ROUND(AA10/$W$1,1),"") | AD10: =IF(AA10=0,0,IF($F10&"/Día"=AC$9,ROUND(AB10/AA10,4),"")) | AE10: =IF(AA10=0,0,IF($F10&"/Día"=AC$9,ROUND(AF10/AA10,4),"")) | AF10: =IF(AA10<>"",$P10,"")
A11: - | B11: I GAS | C11: Servicios | D11: Mes | E11: F1 | F11: MM BTU | H11: 216169.9 | J11: 3.0904 | N11: 1871.49 | O11: =ROUND(G11*I11,2)+ROUND(H11*J11,2)-K11-L11-M11-N11 -> 666179.97 | P11: =ROUND(18.75%*O11,2) -> 124908.74 | Q11: =ROUND($O11*R11,2) -> 99927 | R11: 0.15 | S11: =ROUND($O11*T11,2) -> 24981.75 | T11: 0.0375 | U11: =IF($F11&"/Día"=W$9,SUM($G11:$H11),"") | V11: =IF(U11<>"",$O11,"") | W11: =IF($F11&"/Día"=W$9,ROUND(U11/$W$1,1),"") | X11: =IF(U11=0,0,IF($F11&"/Día"=W$9,ROUND(V11/U11,4),"")) | Y11: =IF(U11=0,0,IF($F11&"/Día"=W$9,ROUND(Z11/U11,4),"")) | Z11: =IF(U11<>"",$P11,"") | AA11: =IF($F11&"/Día"=AC$9,SUM($G11:$H11),"") -> 216169.9 | AB11: =IF(AA11<>"",$O11,"") -> 666179.97 | AC11: =IF($F11&"/Día"=AC$9,ROUND(AA11/$W$1,1),"") -> 7720.4 | AD11: =IF(AA11=0,0,IF($F11&"/Día"=AC$9,ROUND(AB11/AA11,4),"")) -> 3.0817 | AE11: =IF(AA11=0,0,IF($F11&"/Día"=AC$9,ROUND(AF11/AA11,4),"")) -> 0.5778 | AF11: =IF(AA11<>"",$P11,"") -> 124908.74
A12: - | B12: II | C12: Licencia | D12: Quincena | E12: F2 | F12: Bls | G12: 4983 | H12: 4008 | I12: 61.567 | J12: 62.1667 | N12: 1725.59 | O12: =ROUND(G12*I12,2)+ROUND(H12*J12,2)-K12-L12-M12-N12 -> 554226.9 | P12: =ROUND(18.75%*O12,2) -> 103917.54 | Q12: =ROUND($O12*R12,2) -> 83134.04 | R12: 0.15 | S12: =ROUND($O12*T12,2) -> 20783.51 | T12: 0.0375 | U12: =IF($F12&"/Día"=W$9,SUM($G12:$H12),"") -> 8991 | V12: =IF(U12<>"",$O12,"") -> 554226.9 | W12: =IF($F12&"/Día"=W$9,ROUND(U12/$W$1,1),"") -> 321.1 | X12: =IF(U12=0,0,IF($F12&"/Día"=W$9,ROUND(V12/U12,4),"")) -> 61.6424 | Y12: =IF(U12=0,0,IF($F12&"/Día"=W$9,ROUND(Z12/U12,4),"")) -> 11.558 | Z12: =IF(U12<>"",$P12,"") -> 103917.54 | AA12: =IF($F12&"/Día"=AC$9,SUM($G12:$H12),"") | AB12: =IF(AA12<>"",$O12,"") | AC12: =IF($F12&"/Día"=AC$9,ROUND(AA12/$W$1,1),"") | AD12: =IF(AA12=0,0,IF($F12&"/Día"=AC$9,ROUND(AB12/AA12,4),"")) | AE12: =IF(AA12=0,0,IF($F12&"/Día"=AC$9,ROUND(AF12/AA12,4),"")) | AF12: =IF(AA12<>"",$P12,"")
A13: - | B13: II-GAS | C13: Servicios | D13: Mes | E13: F1 | F13: MM BTU | G13: 43900.054 | H13: 35893.615 | I13: 2.6775 | J13: 2.6775 | N13: 1842.63 | O13: =ROUND(G13*I13,2)+ROUND(H13*J13,2)-K13-L13-M13-N13 -> 211804.92 | P13: =ROUND(18.75%*O13,2) -> 39713.42 | Q13: =ROUND($O13*R13,2) -> 31770.74 | R13: 0.15 | S13: =ROUND($O13*T13,2) -> 7942.68 | T13: 0.0375 | U13: =IF($F13&"/Día"=W$9,SUM($G13:$H13),"") | V13: =IF(U13<>"",$O13,"") | W13: =IF($F13&"/Día"=W$9,ROUND(U13/$W$1,1),"") | X13: =IF(U13=0,0,IF($F13&"/Día"=W$9,ROUND(V13/U13,4),"")) | Y13: =IF(U13=0,0,IF($F13&"/Día"=W$9,ROUND(Z13/U13,4),"")) | Z13: =IF(U13<>"",$P13,"") | AA13: =IF($F13&"/Día"=AC$9,SUM($G13:$H13),"") -> 79793.67 | AB13: =IF(AA13<>"",$O13,"") -> 211804.92 | AC13: =IF($F13&"/Día"=AC$9,ROUND(AA13/$W$1,1),"") -> 2849.8 | AD13: =IF(AA13=0,0,IF($F13&"/Día"=AC$9,ROUND(AB13/AA13,4),"")) -> 2.6544 | AE13: =IF(AA13=0,0,IF($F13&"/Día"=AC$9,ROUND(AF13/AA13,4),"")) -> 0.4977 | AF13: =IF(AA13<>"",$P13,"") -> 39713.42
A14: - | B14: III | C14: Licencia | D14: Quincena | E14: F2 | F14: Bls | G14: 12004 | H14: 10139 | I14: 62.8598 | J14: 63.2373 | N14: 1229.36 | O14: =ROUND(G14*I14,2)+ROUND(H14*J14,2)-K14-L14-M14-N14 -> 1394502.7 | P14: =ROUND(18.75%*O14,2) -> 261469.25 | Q14: =ROUND($O14*R14,2) -> 209175.4 | R14: 0.15 | S14: =ROUND($O14*T14,2) -> 52293.85 | T14: 0.0375 | U14: =IF($F14&"/Día"=W$9,SUM($G14:$H14),"") -> 22143 | V14: =IF(U14<>"",$O14,"") -> 1394502.7 | W14: =IF($F14&"/Día"=W$9,ROUND(U14/$W$1,1),"") -> 790.8 | X14: =IF(U14=0,0,IF($F14&"/Día"=W$9,ROUND(V14/U14,4),"")) -> 62.9771 | Y14: =IF(U14=0,0,IF($F14&"/Día"=W$9,ROUND(Z14/U14,4),"")) -> 11.8082 | Z14: =IF(U14<>"",$P14,"") -> 261469.25 | AA14: =IF($F14&"/Día"=AC$9,SUM($G14:$H14),"") | AB14: =IF(AA14<>"",$O14,"") | AC14: =IF($F14&"/Día"=AC$9,ROUND(AA14/$W$1,1),"") | AD14: =IF(AA14=0,0,IF($F14&"/Día"=AC$9,ROUND(AB14/AA14,4),"")) | AE14: =IF(AA14=0,0,IF($F14&"/Día"=AC$9,ROUND(AF14/AA14,4),"")) | AF14: =IF(AA14<>"",$P14,"")
A15: - | B15: IV | C15: Licencia | D15: Quincena | E15: F2 | F15: Bls | G15: 23016 | H15: 24801 | I15: 62.8598 | J15: 63.2373 | N15: 3175.04 | O15: =ROUND(G15*I15,2)+ROUND(H15*J15,2)-K15-L15-M15-N15 -> 3011954.4 | P15: =ROUND(18.75%*O15,2) -> 564741.45 | Q15: =ROUND($O15*R15,2) -> 451793.16 | R15: 0.15 | S15: =ROUND($O15*T15,2) -> 112948.29 | T15: 0.0375 | U15: =IF($F15&"/Día"=W$9,SUM($G15:$H15),"") -> 47817 | V15: =IF(U15<>"",$O15,"") -> 3011954.4 | W15: =IF($F15&"/Día"=W$9,ROUND(U15/$W$1,1),"") -> 1707.8 | X15: =IF(U15=0,0,IF($F15&"/Día"=W$9,ROUND(V15/U15,4),"")) -> 62.9892 | Y15: =IF(U15=0,0,IF($F15&"/Día"=W$9,ROUND(Z15/U15,4),"")) -> 11.8105 | Z15: =IF(U15<>"",$P15,"") -> 564741.45 | AA15: =IF($F15&"/Día"=AC$9,SUM($G15:$H15),"") | AB15: =IF(AA15<>"",$O15,"") | AC15: =IF($F15&"/Día"=AC$9,ROUND(AA15/$W$1,1),"") | AD15: =IF(AA15=0,0,IF($F15&"/Día"=AC$9,ROUND(AB15/AA15,4),"")) | AE15: =IF(AA15=0,0,IF($F15&"/Día"=AC$9,ROUND(AF15/AA15,4),"")) | AF15: =IF(AA15<>"",$P15,"")
A16: - | B16: V | C16: Servicios | D16: Mes | E16: F1 | F16: Bls | H16: 2270 | J16: 63.0188 | N16: 1454.5 | O16: =ROUND(G16*I16,2)+ROUND(H16*J16,2)-K16-L16-M16-N16 -> 141598.18 | P16: =ROUND(18.75%*O16,2) -> 26549.66 | Q16: =ROUND($O16*R16,2) -> 21239.73 | R16: 0.15 | S16: =ROUND($O16*T16,2) -> 5309.93 | T16: 0.0375 | U16: =IF($F16&"/Día"=W$9,SUM($G16:$H16),"") -> 2270 | V16: =IF(U16<>"",$O16,"") -> 141598.18 | W16: =IF($F16&"/Día"=W$9,ROUND(U16/$W$1,1),"") -> 81.1 | X16: =IF(U16=0,0,IF($F16&"/Día"=W$9,ROUND(V16/U16,4),"")) -> 62.3781 | Y16: =IF(U16=0,0,IF($F16&"/Día"=W$9,ROUND(Z16/U16,4),"")) -> 11.6959 | Z16: =IF(U16<>"",$P16,"") -> 26549.66 | AA16: =IF($F16&"/Día"=AC$9,SUM($G16:$H16),"") | AB16: =IF(AA16<>"",$O16,"") | AC16: =IF($F16&"/Día"=AC$9,ROUND(AA16/$W$1,1),"") | AD16: =IF(AA16=0,0,IF($F16&"/Día"=AC$9,ROUND(AB16/AA16,4),"")) | AE16: =IF(AA16=0,0,IF($F16&"/Día"=AC$9,ROUND(AF16/AA16,4),"")) | AF16: =IF(AA16<>"",$P16,"")
A17: - | B17: VII/VI | C17: Licencia | D17: Quincena | E17: F2 | F17: Bls | G17: 55352 | H17: 55652 | I17: 62.3098 | J17: 62.6873 | N17: 2172.48 | O17: =ROUND(G17*I17,2)+ROUND(H17*J17,2)-K17-L17-M17-N17 -> 6935473.2 | P17: =ROUND(18.75%*O17,2) -> 1300401.2 | Q17: =ROUND($O17*R17,2) -> 1040321 | R17: 0.15 | S17: =ROUND($O17*T17,2) -> 260080.24 | T17: 0.0375 | U17: =IF($F17&"/Día"=W$9,SUM($G17:$H17),"") -> 111004 | V17: =IF(U17<>"",$O17,"") -> 6935473.2 | W17: =IF($F17&"/Día"=W$9,ROUND(U17/$W$1,1),"") -> 3964.4 | X17: =IF(U17=0,0,IF($F17&"/Día"=W$9,ROUND(V17/U17,4),"")) -> 62.4795 | Y17: =IF(U17=0,0,IF($F17&"/Día"=W$9,ROUND(Z17/U17,4),"")) -> 11.7149 | Z17: =IF(U17<>"",$P17,"") -> 1300401.2 | AA17: =IF($F17&"/Día"=AC$9,SUM($G17:$H17),"") | AB17: =IF(AA17<>"",$O17,"") | AC17: =IF($F17&"/Día"=AC$9,ROUND(AA17/$W$1,1),"") | AD17: =IF(AA17=0,0,IF($F17&"/Día"=AC$9,ROUND(AB17/AA17,4),"")) | AE17: =IF(AA17=0,0,IF($F17&"/Día"=AC$9,ROUND(AF17/AA17,4),"")) | AF17: =IF(AA17<>"",$P17,"")
A18: - | B18: VII | C18: Servicios | D18: Mes | E18: F1 | F18: Bls | O18: =ROUND(G18*I18,2)+ROUND(H18*J18,2)-K18-L18-M18-N18 -> 0 | P18: =ROUND(18.75%*O18,2) -> 0 | Q18: =ROUND($O18*R18,2) -> 0 | R18: 0.15 | S18: =ROUND($O18*T18,2) -> 0 | T18: 0.0375 | U18: =IF($F18&"/Día"=W$9,SUM($G18:$H18),"") -> 0 | V18: =IF(U18<>"",$O18,"") -> 0 | W18: =IF($F18&"/Día"=W$9,ROUND(U18/$W$1,1),"") -> 0 | X18: =IF(U18=0,0,IF($F18&"/Día"=W$9,ROUND(V18/U18,4),"")) -> 0 | Y18: =IF(U18=0,0,IF($F18&"/Día"=W$9,ROUND(Z18/U18,4),"")) -> 0 | Z18: =IF(U18<>"",$P18,"") -> 0 | AA18: =IF($F18&"/Día"=AC$9,SUM($G18:$H18),"") | AB18: =IF(AA18<>"",$O18,"") | AC18: =IF($F18&"/Día"=AC$9,ROUND(AA18/$W$1,1),"") | AD18: =IF(AA18=0,0,IF($F18&"/Día"=AC$9,ROUND(AB18/AA18,4),"")) | AE18: =IF(AA18=0,0,IF($F18&"/Día"=AC$9,ROUND(AF18/AA18,4),"")) | AF18: =IF(AA18<>"",$P18,"")
A19: - | B19: VII/VI-GAS | C19: Licencia | D19: Quincena | E19: F2 | F19: MM BTU | G19: 58427.63 | H19: 50453.55 | I19: 2.2141 | J19: 2.2141 | N19: 2074.48 | O19: =ROUND(G19*I19,2)+ROUND(H19*J19,2)-K19-L19-M19-N19 -> 238999.35 | P19: =ROUND(18.75%*O19,2) -> 44812.38 | Q19: =ROUND($O19*R19,2) -> 35849.9 | R19: 0.15 | S19: =ROUND($O19*T19,2) -> 8962.48 | T19: 0.0375 | U19: =IF($F19&"/Día"=W$9,SUM($G19:$H19),"") | V19: =IF(U19<>"",$O19,"") | W19: =IF($F19&"/Día"=W$9,ROUND(U19/$W$1,1),"") | X19: =IF(U19=0,0,IF($F19&"/Día"=W$9,ROUND(V19/U19,4),"")) | Y19: =IF(U19=0,0,IF($F19&"/Día"=W$9,ROUND(Z19/U19,4),"")) | Z19: =IF(U19<>"",$P19,"") | AA19: =IF($F19&"/Día"=AC$9,SUM($G19:$H19),"") -> 108881.18 | AB19: =IF(AA19<>"",$O19,"") -> 238999.35 | AC19: =IF($F19&"/Día"=AC$9,ROUND(AA19/$W$1,1),"") -> 3888.6 | AD19: =IF(AA19=0,0,IF($F19&"/Día"=AC$9,ROUND(AB19/AA19,4),"")) -> 2.195 | AE19: =IF(AA19=0,0,IF($F19&"/Día"=AC$9,ROUND(AF19/AA19,4),"")) -> 0.4116 | AF19: =IF(AA19<>"",$P19,"") -> 44812.38
A20: - | B20: IX | C20: Licencia | D20: Quincena | E20: F2 | F20: Bls | G20: 2061 | H20: 2919 | I20: 62.8598 | J20: 63.2373 | N20: 721.38 | O20: =ROUND(G20*I20,2)+ROUND(H20*J20,2)-K20-L20-M20-N20 -> 313422.35 | P20: =ROUND(18.75%*O20,2) -> 58766.69 | Q20: =ROUND($O20*R20,2) -> 47013.35 | R20: 0.15 | S20: =ROUND($O20*T20,2) -> 11753.34 | T20: 0.0375 | U20: =IF($F20&"/Día"=W$9,SUM($G20:$H20),"") -> 4980 | V20: =IF(U20<>"",$O20,"") -> 313422.35 | W20: =IF($F20&"/Día"=W$9,ROUND(U20/$W$1,1),"") -> 177.9 | X20: =IF(U20=0,0,IF($F20&"/Día"=W$9,ROUND(V20/U20,4),"")) -> 62.9362 | Y20: =IF(U20=0,0,IF($F20&"/Día"=W$9,ROUND(Z20/U20,4),"")) -> 11.8005 | Z20: =IF(U20<>"",$P20,"") -> 58766.69 | AA20: =IF($F20&"/Día"=AC$9,SUM($G20:$H20),"") | AB20: =IF(AA20<>"",$O20,"") | AC20: =IF($F20&"/Día"=AC$9,ROUND(AA20/$W$1,1),"") | AD20: =IF(AA20=0,0,IF($F20&"/Día"=AC$9,ROUND(AB20/AA20,4),"")) | AE20: =IF(AA20=0,0,IF($F20&"/Día"=AC$9,ROUND(AF20/AA20,4),"")) | AF20: =IF(AA20<>"",$P20,"")
A21: - | B21: X | C21: Licencia | D21: Quincena | E21: F2 | F21: Bls | G21: 194807 | H21: 167968 | I21: 62.8598 | J21: 63.2373 | N21: 4237.82 | O21: =ROUND(G21*I21,2)+ROUND(H21*J21,2)-K21-L21-M21-N21 -> 22863134 | P21: =ROUND(18.75%*O21,2) -> 4286837.6 | Q21: =ROUND($O21*R21,2) -> 3429470.1 | R21: 0.15 | S21: =ROUND($O21*T21,2) -> 857367.53 | T21: 0.0375 | U21: =IF($F21&"/Día"=W$9,SUM($G21:$H21),"") -> 362775 | V21: =IF(U21<>"",$O21,"") -> 22863134 | W21: =IF($F21&"/Día"=W$9,ROUND(U21/$W$1,1),"") -> 12956.3 | X21: =IF(U21=0,0,IF($F21&"/Día"=W$9,ROUND(V21/U21,4),"")) -> 63.0229 | Y21: =IF(U21=0,0,IF($F21&"/Día"=W$9,ROUND(Z21/U21,4),"")) -> 11.8168 | Z21: =IF(U21<>"",$P21,"") -> 4286837.6 | AA21: =IF($F21&"/Día"=AC$9,SUM($G21:$H21),"") | AB21: =IF(AA21<>"",$O21,"") | AC21: =IF($F21&"/Día"=AC$9,ROUND(AA21/$W$1,1),"") | AD21: =IF(AA21=0,0,IF($F21&"/Día"=AC$9,ROUND(AB21/AA21,4),"")) | AE21: =IF(AA21=0,0,IF($F21&"/Día"=AC$9,ROUND(AF21/AA21,4),"")) | AF21: =IF(AA21<>"",$P21,"")
A22: - | B22: X-GAS | C22: Licencia | D22: Mes | E22: F2 | F22: MM BTU | G22: 247038.94 | H22: 210769.83 | I22: 1.7948 | J22: 1.7948 | N22: 2185.46 | O22: =ROUND(G22*I22,2)+ROUND(H22*J22,2)-K22-L22-M22-N22 -> 819489.72 | P22: =ROUND(18.75%*O22,2) -> 153654.32 | Q22: =ROUND($O22*R22,2) -> 122923.46 | R22: 0.15 | S22: =ROUND($O22*T22,2) -> 30730.86 | T22: 0.0375 | U22: =IF($F22&"/Día"=W$9,SUM($G22:$H22),"") | V22: =IF(U22<>"",$O22,"") | W22: =IF($F22&"/Día"=W$9,ROUND(U22/$W$1,1),"") | X22: =IF(U22=0,0,IF($F22&"/Día"=W$9,ROUND(V22/U22,4),"")) | Y22: =IF(U22=0,0,IF($F22&"/Día"=W$9,ROUND(Z22/U22,4),"")) | Z22: =IF(U22<>"",$P22,"") | AA22: =IF($F22&"/Día"=AC$9,SUM($G22:$H22),"") -> 457808.77 | AB22: =IF(AA22<>"",$O22,"") -> 819489.72 | AC22: =IF($F22&"/Día"=AC$9,ROUND(AA22/$W$1,1),"") -> 16350.3 | AD22: =IF(AA22=0,0,IF($F22&"/Día"=AC$9,ROUND(AB22/AA22,4),"")) -> 1.79 | AE22: =IF(AA22=0,0,IF($F22&"/Día"=AC$9,ROUND(AF22/AA22,4),"")) -> 0.3356 | AF22: =IF(AA22<>"",$P22,"") -> 153654.32
A23: - | B23: XIV | C23: Licencia | D23: Mes | E23: F2 | F23: Bls | O23: =ROUND(G23*I23,2)+ROUND(H23*J23,2)-K23-L23-M23-N23 -> 0 | P23: =ROUND(18.75%*O23,2) -> 0 | Q23: =ROUND($O23*R23,2) -> 0 | R23: 0.15 | S23: =ROUND($O23*T23,2) -> 0 | T23: 0.0375 | U23: =IF($F23&"/Día"=W$9,SUM($G23:$H23),"") -> 0 | V23: =IF(U23<>"",$O23,"") -> 0 | W23: =IF($F23&"/Día"=W$9,ROUND(U23/$W$1,1),"") -> 0 | X23: =IF(U23=0,0,IF($F23&"/Día"=W$9,ROUND(V23/U23,4),"")) -> 0 | Y23: =IF(U23=0,0,IF($F23&"/Día"=W$9,ROUND(Z23/U23,4),"")) -> 0 | Z23: =IF(U23<>"",$P23,"") -> 0 | AA23: =IF($F23&"/Día"=AC$9,SUM($G23:$H23),"") | AB23: =IF(AA23<>"",$O23,"") | AC23: =IF($F23&"/Día"=AC$9,ROUND(AA23/$W$1,1),"") | AD23: =IF(AA23=0,0,IF($F23&"/Día"=AC$9,ROUND(AB23/AA23,4),"")) | AE23: =IF(AA23=0,0,IF($F23&"/Día"=AC$9,ROUND(AF23/AA23,4),"")) | AF23: =IF(AA23<>"",$P23,"")
A24: - | B24: XV | C24: Licencia | D24: Quincena | E24: F2 | F24: Bls | G24: 565 | H24: 574 | I24: 63.8679 | J24: 64.3152 | N24: 784.43 | O24: =ROUND(G24*I24,2)+ROUND(H24*J24,2)-K24-L24-M24-N24 -> 72217.85 | P24: =ROUND(18.75%*O24,2) -> 13540.85 | Q24: =ROUND($O24*R24,2) -> 10832.68 | R24: 0.15 | S24: =ROUND($O24*T24,2) -> 2708.17 | T24: 0.0375 | U24: =IF($F24&"/Día"=W$9,SUM($G24:$H24),"") -> 1139 | V24: =IF(U24<>"",$O24,"") -> 72217.85 | W24: =IF($F24&"/Día"=W$9,ROUND(U24/$W$1,1),"") -> 40.7 | X24: =IF(U24=0,0,IF($F24&"/Día"=W$9,ROUND(V24/U24,4),"")) -> 63.4046 | Y24: =IF(U24=0,0,IF($F24&"/Día"=W$9,ROUND(Z24/U24,4),"")) -> 11.8884 | Z24: =IF(U24<>"",$P24,"") -> 13540.85 | AA24: =IF($F24&"/Día"=AC$9,SUM($G24:$H24),"") | AB24: =IF(AA24<>"",$O24,"") | AC24: =IF($F24&"/Día"=AC$9,ROUND(AA24/$W$1,1),"") | AD24: =IF(AA24=0,0,IF($F24&"/Día"=AC$9,ROUND(AB24/AA24,4),"")) | AE24: =IF(AA24=0,0,IF($F24&"/Día"=AC$9,ROUND(AF24/AA24,4),"")) | AF24: =IF(AA24<>"",$P24,"")
A25: - | B25: XIII Crudo | C25: Licencia | D25: Quincena | E25: F2 | F25: Bls | G25: 29918 | H25: 27066 | I25: 62.8598 | J25: 63.2373 | N25: 1496.45 | O25: =ROUND(G25*I25,2)+ROUND(H25*J25,2)-K25-L25-M25-N25 -> 3590723.8 | P25: =ROUND(18.75%*O25,2) -> 673260.71 | Q25: =ROUND($O25*R25,2) -> 538608.57 | R25: 0.15 | S25: =ROUND($O25*T25,2) -> 134652.14 | T25: 0.0375 | U25: =IF($F25&"/Día"=W$9,SUM($G25:$H25),"") -> 56984 | V25: =IF(U25<>"",$O25,"") -> 3590723.8 | W25: =IF($F25&"/Día"=W$9,ROUND(U25/$W$1,1),"") -> 2035.1 | X25: =IF(U25=0,0,IF($F25&"/Día"=W$9,ROUND(V25/U25,4),"")) -> 63.0128 | Y25: =IF(U25=0,0,IF($F25&"/Día"=W$9,ROUND(Z25/U25,4),"")) -> 11.8149 | Z25: =IF(U25<>"",$P25,"") -> 673260.71 | AA25: =IF($F25&"/Día"=AC$9,SUM($G25:$H25),"") | AB25: =IF(AA25<>"",$O25,"") | AC25: =IF($F25&"/Día"=AC$9,ROUND(AA25/$W$1,1),"") | AD25: =IF(AA25=0,0,IF($F25&"/Día"=AC$9,ROUND(AB25/AA25,4),"")) | AE25: =IF(AA25=0,0,IF($F25&"/Día"=AC$9,ROUND(AF25/AA25,4),"")) | AF25: =IF(AA25<>"",$P25,"")
A26: - | B26: XIII COND | C26: Licencia | D26: Quincena | E26: F2 | F26: Bls | O26: =ROUND(G26*I26,2)+ROUND(H26*J26,2)-K26-L26-M26-N26 -> 0 | P26: =ROUND(18.75%*O26,2) -> 0 | Q26: =ROUND($O26*R26,2) -> 0 | R26: 0.15 | S26: =ROUND($O26*T26,2) -> 0 | T26: 0.0375 | U26: =IF($F26&"/Día"=W$9,SUM($G26:$H26),"") -> 0 | V26: =IF(U26<>"",$O26,"") -> 0 | W26: =IF($F26&"/Día"=W$9,ROUND(U26/$W$1,1),"") -> 0 | X26: =IF(U26=0,0,IF($F26&"/Día"=W$9,ROUND(V26/U26,4),"")) -> 0 | Y26: =IF(U26=0,0,IF($F26&"/Día"=W$9,ROUND(Z26/U26,4),"")) -> 0 | Z26: =IF(U26<>"",$P26,"") -> 0 | AA26: =IF($F26&"/Día"=AC$9,SUM($G26:$H26),"") | AB26: =IF(AA26<>"",$O26,"") | AC26: =IF($F26&"/Día"=AC$9,ROUND(AA26/$W$1,1),"") | AD26: =IF(AA26=0,0,IF($F26&"/Día"=AC$9,ROUND(AB26/AA26,4),"")) | AE26: =IF(AA26=0,0,IF($F26&"/Día"=AC$9,ROUND(AF26/AA26,4),"")) | AF26: =IF(AA26<>"",$P26,"")
A27: - | B27: XIII Gas | C27: Licencia | D27: Quincena | E27: F2 | F27: MM BTU | G27: =80755.7378+108003.1931 -> 188758.93 | H27: =93892.9507+84259.4053 -> 178152.36 | I27: 2.5834234 | J27: 2.6983454 | N27: 3092.96 | O27: =ROUND(G27*I27,2)+ROUND(H27*J27,2)-K27-L27-M27-N27 -> 965267.86 | P27: =ROUND(18.75%*O27,2) -> 180987.72 | Q27: =ROUND($O27*R27,2) -> 144790.18 | R27: 0.15 | S27: =ROUND($O27*T27,2) -> 36197.54 | T27: 0.0375 | U27: =IF($F27&"/Día"=W$9,SUM($G27:$H27),"") | V27: =IF(U27<>"",$O27,"") | W27: =IF($F27&"/Día"=W$9,ROUND(U27/$W$1,1),"") | X27: =IF(U27=0,0,IF($F27&"/Día"=W$9,ROUND(V27/U27,4),"")) | Y27: =IF(U27=0,0,IF($F27&"/Día"=W$9,ROUND(Z27/U27,4),"")) | Z27: =IF(U27<>"",$P27,"") | AA27: =IF($F27&"/Día"=AC$9,SUM($G27:$H27),"") -> 366911.29 | AB27: =IF(AA27<>"",$O27,"") -> 965267.86 | AC27: =IF($F27&"/Día"=AC$9,ROUND(AA27/$W$1,1),"") -> 13104 | AD27: =IF(AA27=0,0,IF($F27&"/Día"=AC$9,ROUND(AB27/AA27,4),"")) -> 2.6308 | AE27: =IF(AA27=0,0,IF($F27&"/Día"=AC$9,ROUND(AF27/AA27,4),"")) -> 0.4933 | AF27: =IF(AA27<>"",$P27,"") -> 180987.72
A28: - | B28: Z-2B | C28: Servicios | D28: Mes | E28: F1 | F28: Bls | H28: =34290+180024 -> 214314 | J28: 60.9661 | N28: 2391.37 | O28: =ROUND(G28*I28,2)+ROUND(H28*J28,2)-K28-L28-M28-N28 -> 13063497 | P28: =ROUND(18.75%*O28,2) -> 2449405.8 | Q28: =ROUND($O28*R28,2) -> 1959524.6 | R28: 0.15 | S28: =ROUND($O28*T28,2) -> 489881.15 | T28: 0.0375 | U28: =IF($F28&"/Día"=W$9,SUM($G28:$H28),"") -> 214314 | V28: =IF(U28<>"",$O28,"") -> 13063497 | W28: =IF($F28&"/Día"=W$9,ROUND(U28/$W$1,1),"") -> 7654.1 | X28: =IF(U28=0,0,IF($F28&"/Día"=W$9,ROUND(V28/U28,4),"")) -> 60.9549 | Y28: =IF(U28=0,0,IF($F28&"/Día"=W$9,ROUND(Z28/U28,4),"")) -> 11.4291 | Z28: =IF(U28<>"",$P28,"") -> 2449405.8 | AA28: =IF($F28&"/Día"=AC$9,SUM($G28:$H28),"") | AB28: =IF(AA28<>"",$O28,"") | AC28: =IF($F28&"/Día"=AC$9,ROUND(AA28/$W$1,1),"") | AD28: =IF(AA28=0,0,IF($F28&"/Día"=AC$9,ROUND(AB28/AA28,4),"")) | AE28: =IF(AA28=0,0,IF($F28&"/Día"=AC$9,ROUND(AF28/AA28,4),"")) | AF28: =IF(AA28<>"",$P28,"")
A29: - | B29: Z-2B GAS | C29: Servicios | D29: Mes | E29: F1 | F29: MM BTU | H29: =177687.13+1019.28+32825.88 -> 211532.29 | J29: 5.2921608 | N29: 2108.8 | O29: =ROUND(G29*I29,2)+ROUND(H29*J29,2)-K29-L29-M29-N29 -> 1117354.1 | P29: =ROUND(18.75%*O29,2) -> 209503.89 | Q29: =ROUND($O29*R29,2) -> 167603.12 | R29: 0.15 | S29: =ROUND($O29*T29,2) -> 41900.78 | T29: 0.0375 | U29: =IF($F29&"/Día"=W$9,SUM($G29:$H29),"") | V29: =IF(U29<>"",$O29,"") | W29: =IF($F29&"/Día"=W$9,ROUND(U29/$W$1,1),"") | X29: =IF(U29=0,0,IF($F29&"/Día"=W$9,ROUND(V29/U29,4),"")) | Y29: =IF(U29=0,0,IF($F29&"/Día"=W$9,ROUND(Z29/U29,4),"")) | Z29: =IF(U29<>"",$P29,"") | AA29: =IF($F29&"/Día"=AC$9,SUM($G29:$H29),"") -> 211532.29 | AB29: =IF(AA29<>"",$O29,"") -> 1117354.1 | AC29: =IF($F29&"/Día"=AC$9,ROUND(AA29/$W$1,1),"") -> 7554.7 | AD29: =IF(AA29=0,0,IF($F29&"/Día"=AC$9,ROUND(AB29/AA29,4),"")) -> 5.2822 | AE29: =IF(AA29=0,0,IF($F29&"/Día"=AC$9,ROUND(AF29/AA29,4),"")) -> 0.9904 | AF29: =IF(AA29<>"",$P29,"") -> 209503.89
A30: - | B30: XX | C30: Licencia | D30: Quincena | E30: F2 | F30: Bls | G30: 326 | H30: 229 | I30: 62.8598 | J30: 63.2373 | N30: 460.72 | O30: =ROUND(G30*I30,2)+ROUND(H30*J30,2)-K30-L30-M30-N30 -> 34512.91 | P30: =ROUND(18.75%*O30,2) -> 6471.17 | Q30: =ROUND($O30*R30,2) -> 1294.23 | R30: 0.0375 | S30: =ROUND($O30*T30,2) -> 5176.94 | T30: 0.15 | U30: =IF($F30&"/Día"=W$9,SUM($G30:$H30),"") -> 555 | V30: =IF(U30<>"",$O30,"") -> 34512.91 | W30: =IF($F30&"/Día"=W$9,ROUND(U30/$W$1,1),"") -> 19.8 | X30: =IF(U30=0,0,IF($F30&"/Día"=W$9,ROUND(V30/U30,4),"")) -> 62.1854 | Y30: =IF(U30=0,0,IF($F30&"/Día"=W$9,ROUND(Z30/U30,4),"")) -> 11.6598 | Z30: =IF(U30<>"",$P30,"") -> 6471.17 | AA30: =IF($F30&"/Día"=AC$9,SUM($G30:$H30),"") | AB30: =IF(AA30<>"",$O30,"") | AC30: =IF($F30&"/Día"=AC$9,ROUND(AA30/$W$1,1),"") | AD30: =IF(AA30=0,0,IF($F30&"/Día"=AC$9,ROUND(AB30/AA30,4),"")) | AE30: =IF(AA30=0,0,IF($F30&"/Día"=AC$9,ROUND(AF30/AA30,4),"")) | AF30: =IF(AA30<>"",$P30,"")
A31: - | B31: Z1 Crudo | C31: Licencia | D31: Quincena | E31: F2 | F31: Bls | G31: 78469 | I31: 62.8598 | N31: 1418.72 | O31: =ROUND(G31*I31,2)+ROUND(H31*J31,2)-K31-L31-M31-N31 -> 4931126.9 | P31: =ROUND(18.75%*O31,2) -> 924586.3 | Q31: =ROUND($O31*R31,2) -> 184917.26 | R31: 0.0375 | S31: =ROUND($O31*T31,2) -> 739669.04 | T31: 0.15 | U31: =IF($F31&"/Día"=W$9,SUM($G31:$H31),"") -> 78469 | V31: =IF(U31<>"",$O31,"") -> 4931126.9 | W31: =IF($F31&"/Día"=W$9,ROUND(U31/$W$1,1),"") -> 2802.5 | X31: =IF(U31=0,0,IF($F31&"/Día"=W$9,ROUND(V31/U31,4),"")) -> 62.8417 | Y31: =IF(U31=0,0,IF($F31&"/Día"=W$9,ROUND(Z31/U31,4),"")) -> 11.7828 | Z31: =IF(U31<>"",$P31,"") -> 924586.3 | AA31: =IF($F31&"/Día"=AC$9,SUM($G31:$H31),"") | AB31: =IF(AA31<>"",$O31,"") | AC31: =IF($F31&"/Día"=AC$9,ROUND(AA31/$W$1,1),"") | AD31: =IF(AA31=0,0,IF($F31&"/Día"=AC$9,ROUND(AB31/AA31,4),"")) | AE31: =IF(AA31=0,0,IF($F31&"/Día"=AC$9,ROUND(AF31/AA31,4),"")) | AF31: =IF(AA31<>"",$P31,"")
A32: - | B32: Z1 Gas | C32: Licencia | D32: Quincena | E32: F2 | F32: MM BTU | O32: =ROUND(G32*I32,2)+ROUND(H32*J32,2)-K32-L32-M32-N32 -> 0 | P32: =ROUND(18.75%*O32,2) -> 0 | Q32: =ROUND($O32*R32,2) -> 0 | R32: 0.0375 | S32: =ROUND($O32*T32,2) -> 0 | T32: 0.15 | U32: =IF($F32&"/Día"=W$9,SUM($G32:$H32),"") | V32: =IF(U32<>"",$O32,"") | W32: =IF($F32&"/Día"=W$9,ROUND(U32/$W$1,1),"") | X32: =IF(U32=0,0,IF($F32&"/Día"=W$9,ROUND(V32/U32,4),"")) | Y32: =IF(U32=0,0,IF($F32&"/Día"=W$9,ROUND(Z32/U32,4),"")) | Z32: =IF(U32<>"",$P32,"") | AA32: =IF($F32&"/Día"=AC$9,SUM($G32:$H32),"") -> 0 | AB32: =IF(AA32<>"",$O32,"") -> 0 | AC32: =IF($F32&"/Día"=AC$9,ROUND(AA32/$W$1,1),"") -> 0 | AD32: =IF(AA32=0,0,IF($F32&"/Día"=AC$9,ROUND(AB32/AA32,4),"")) -> 0 | AE32: =IF(AA32=0,0,IF($F32&"/Día"=AC$9,ROUND(AF32/AA32,4),"")) -> 0 | AF32: =IF(AA32<>"",$P32,"") -> 0
A33: - | B33: Z-2B - LGN | C33: Servicios | D33: Mes | E33: F1 | F33: Bls | H33: =4658+24454 -> 29112 | J33: 56.8538 | N33: 2297.09 | O33: =ROUND(G33*I33,2)+ROUND(H33*J33,2)-K33-L33-M33-N33 -> 1652830.7 | P33: =ROUND(18.75%*O33,2) -> 309905.76 | Q33: =ROUND($O33*R33,2) -> 247924.61 | R33: 0.15 | S33: =ROUND($O33*T33,2) -> 61981.15 | T33: 0.0375 | U33: =IF($F33&"/Día"=W$9,SUM($G33:$H33),"") -> 29112 | V33: =IF(U33<>"",$O33,"") -> 1652830.7 | W33: =IF($F33&"/Día"=W$9,ROUND(U33/$W$1,1),"") -> 1039.7 | X33: =IF(U33=0,0,IF($F33&"/Día"=W$9,ROUND(V33/U33,4),"")) -> 56.7749 | Y33: =IF(U33=0,0,IF($F33&"/Día"=W$9,ROUND(Z33/U33,4),"")) -> 10.6453 | Z33: =IF(U33<>"",$P33,"") -> 309905.76 | AA33: =IF($F33&"/Día"=AC$9,SUM($G33:$H33),"") | AB33: =IF(AA33<>"",$O33,"") | AC33: =IF($F33&"/Día"=AC$9,ROUND(AA33/$W$1,1),"") | AD33: =IF(AA33=0,0,IF($F33&"/Día"=AC$9,ROUND(AB33/AA33,4),"")) | AE33: =IF(AA33=0,0,IF($F33&"/Día"=AC$9,ROUND(AF33/AA33,4),"")) | AF33: =IF(AA33<>"",$P33,"")
A34: - | B34: Z-6 | C34: Licencia | D34: Quincena | E34: F2 | F34: MM BTU | O34: =ROUND(G34*I34,2)+ROUND(H34*J34,2)-K34-L34-M34-N34 -> 0 | P34: =ROUND(18.75%*O34,2) -> 0 | Q34: =ROUND($O34*R34,2) -> 0 | R34: 0.15 | S34: =ROUND($O34*T34,2) -> 0 | T34: 0.0375
A35: - | B35: Ajustes meses anteriores (1) | O35: =+O211 -> -23589.88 | P35: =+P211 -> -4423.1 | Q35: =+Q211 -> -3538.48 | S35: =+S211 -> -884.62 | U35: =IF($F35&"/Día"=W$9,SUM($G35:$H35),"") | V35: =IF(U35<>"",$O35,"") | W35: =IF($F35&"/Día"=W$9,ROUND(U35/$W$1,1),"") | X35: =IF(U35=0,0,IF($F35&"/Día"=W$9,ROUND(V35/U35,4),"")) | Y35: =IF(U35=0,0,IF($F35&"/Día"=W$9,ROUND(Z35/U35,4),"")) | Z35: =IF(U35<>"",$P35,"") | AA35: =IF($F35&"/Día"=AC$9,SUM($G35:$H35),"") | AB35: =IF(AA35<>"",$O35,"") | AC35: =IF($F35&"/Día"=AC$9,ROUND(AA35/$W$1,1),"") | AD35: =IF(AA35=0,0,IF($F35&"/Día"=AC$9,ROUND(AB35/AA35,4),"")) | AE35: =IF(AA35=0,0,IF($F35&"/Día"=AC$9,ROUND(AF35/AA35,4),"")) | AF35: =IF(AA35<>"",$P35,"")
B36: Subtotal | C36: =TEXT(A$9,)&" US$" -> Piura / Tumbes US$ | O36: =SUM(O10:O35) -> 63879786 | P36: =SUM(P10:P35) -> 11977460 | Q36: =SUM(Q10:Q35) -> 9023333.4 | S36: =SUM(S10:S35) -> 2954126.4 | U36: =SUM(U10:U35) -> 961590 | V36: =SUM(V10:V35) -> 59884279 | W36: =SUM(W10:W35) -> 34342.6 | X36: =ROUND(V36/U36,4) -> 62.2763 | Y36: =ROUND(Z36/U36,4) -> 11.6768 | Z36: =SUM(Z10:Z35) -> 11228302 | AA36: =SUM(AA10:AA35) -> 1441097.1 | AB36: =SUM(AB10:AB35) -> 4019095.9 | AC36: =SUM(AC10:AC35) -> 51467.8 | AD36: =ROUND(AB36/AA36,4) -> 2.7889 | AE36: =ROUND(AF36/AA36,4) -> 0.5229 | AF36: =SUM(AF10:AF35) -> 753580.47 | AG36: =P36-Z36-AF36 -> -4423.1
C37: =TEXT(A$9,)&" S/." -> Piura / Tumbes S/. | P37: =ROUND($F$1*P36,2) -> 0 | Q37: =ROUND($F$1*Q36,2) -> 0 | S37: =ROUND($F$1*S36,2) -> 0
A38: Provincia Puerto Inca Huanuco | Q38: Puerto Inca
A39: - | B39: 31-D | C39: Licencia | D39: Quincena | E39: F2 | F39: Bls | G39: 454 | I39: 64.2445 | N39: 1087.7 | O39: =ROUND(G39*I39,2)+ROUND(H39*J39,2)-K39-L39-M39-N39 -> 28079.3 | P39: =ROUND(15%*O39,2) -> 4211.9 | Q39: =ROUND($O39*R39,2) -> 4211.9 | R39: 0.15 | U39: =IF($F39&"/Día"=W$9,SUM($G39:$H39),"") -> 454 | V39: =IF(U39<>"",$O39,"") -> 28079.3 | W39: =IF($F39&"/Día"=W$9,ROUND(U39/$W$1,1),"") -> 16.2 | X39: =IF(U39=0,0,IF($F39&"/Día"=W$9,ROUND(V39/U39,4),"")) -> 61.8487 | Y39: =IF(U39=0,0,IF($F39&"/Día"=W$9,ROUND(Z39/U39,4),"")) -> 9.2773 | Z39: =IF(U39<>"",$P39,"") -> 4211.9 | AA39: =IF($F39&"/Día"=AC$9,SUM($G39:$H39),"") | AB39: =IF(AA39<>"",$O39,"") | AC39: =IF($F39&"/Día"=AC$9,ROUND(AA39/$W$1,1),"") | AD39: =IF(AA39=0,0,IF($F39&"/Día"=AC$9,ROUND(AB39/AA39,4),"")) | AE39: =IF(AA39=0,0,IF($F39&"/Día"=AC$9,ROUND(AF39/AA39,4),"")) | AF39: =IF(AA39<>"",$P39,"")
A40: - | B40: 131 | C40: Licencia | D40: Quincena | E40: F2 | F40: Bls | G40: 41216 | H40: 37648 | I40: 60.8419 | J40: 61.4912 | N40: 9234.9 | O40: =ROUND(G40*I40,2)+ROUND(H40*J40,2)-K40-L40-M40-N40 -> 4813445.5 | P40: =ROUND(15%*O40,2) -> 722016.83 | Q40: =ROUND($O40*R40,2) -> 722016.83 | R40: 0.15 | U40: =IF($F40&"/Día"=W$9,SUM($G40:$H40),"") -> 78864 | V40: =IF(U40<>"",$O40,"") -> 4813445.5 | W40: =IF($F40&"/Día"=W$9,ROUND(U40/$W$1,1),"") -> 2816.6 | X40: =IF(U40=0,0,IF($F40&"/Día"=W$9,ROUND(V40/U40,4),"")) -> 61.0348 | Y40: =IF(U40=0,0,IF($F40&"/Día"=W$9,ROUND(Z40/U40,4),"")) -> 9.1552 | Z40: =IF(U40<>"",$P40,"") -> 722016.83 | AA40: =IF($F40&"/Día"=AC$9,SUM($G40:$H40),"") | AB40: =IF(AA40<>"",$O40,"") | AC40: =IF($F40&"/Día"=AC$9,ROUND(AA40/$W$1,1),"") | AD40: =IF(AA40=0,0,IF($F40&"/Día"=AC$9,ROUND(AB40/AA40,4),"")) | AE40: =IF(AA40=0,0,IF($F40&"/Día"=AC$9,ROUND(AF40/AA40,4),"")) | AF40: =IF(AA40<>"",$P40,"")
A41: - | B41: Ajustes meses anteriores (2) | O41: =+O214 -> 0 | P41: =+P214 -> -166.87 | Q41: =+Q214 -> -166.87 | U41: =IF($F41&"/Día"=W$9,SUM($G41:$H41),"") | V41: =IF(U41<>"",$O41,"") | W41: =IF($F41&"/Día"=W$9,ROUND(U41/$W$1,1),"") | X41: =IF(U41=0,0,IF($F41&"/Día"=W$9,ROUND(V41/U41,4),"")) | Y41: =IF(U41=0,0,IF($F41&"/Día"=W$9,ROUND(Z41/U41,4),"")) | Z41: =IF(U41<>"",$P41,"") | AA41: =IF($F41&"/Día"=AC$9,SUM($G41:$H41),"") | AB41: =IF(AA41<>"",$O41,"") | AC41: =IF($F41&"/Día"=AC$9,ROUND(AA41/$W$1,1),"") | AD41: =IF(AA41=0,0,IF($F41&"/Día"=AC$9,ROUND(AB41/AA41,4),"")) | AE41: =IF(AA41=0,0,IF($F41&"/Día"=AC$9,ROUND(AF41/AA41,4),"")) | AF41: =IF(AA41<>"",$P41,"")
...

Sheet Abr (2)
A1: Período de Cálculo: | E1: 43191 | U1: Días en el mes | W1: =DATE(YEAR(E1),MONTH(E1)+1,1)-DATE(YEAR(E1),MONTH(E1),1) -> 30
A2: PERUPETRO S.A.
A3: DETERMINACION DEL CANON, SOBRECANON y PARTICIPACION (US$)
A4: ="Correspondiente a "&TEXT(E1,"MMMMMMM YYYY") -> Correspondiente a abril 2018
A5: ="Tipo de Cambio= "&TEXT(F1,"0.000") -> Tipo de Cambio= 0.000
A7: Localidad | C7: Modalidad de Contrato | D7: Calculo del Canon | F7: Volumen Producción / Venta | I7: Canasta o Valor Venta (US$/Unidad) | K7: Deducción de Gastos para determinación de valor de producción en Punto de Fiscalización (US$) | O7: Valor de la Producción (US$) | P7: Canon y Sobrecanon / Participación (US$) | U7: Resumen por Petróleo y Condensados | AA7: Resumen por Gas Natural | AG7: Control
A8: - Lote | D8: Período | E8: Fórmula | F8: Unidades | G8: 1ra. Q | H8: 2da. Q / Mes | I8: 1ra. Q | J8: 2da. Q / Mes | K8: Flete Marítimo | L8: Comercialización | M8: Oleoducto | N8: Fiscalización | P8: Total | Q8: Localidad 1 | S8: Localidad 2 | U8: Producción / Venta | X8: Valor Prod | Y8: Valor Canon | AA8: Producción / Venta | AD8: Valor Prod | AE8: Valor Canon | AG8: Total
A9: Piura / Tumbes | Q9: Piura | S9: Tumbes | U9: Bls/Mes | V9: V P (US$) | W9: Bls/Día | X9: US$/Bl | Y9: US$/Bl | Z9: US$ | AA9: MM BTU/Mes | AB9: V P (US$) | AC9: MM BTU/Día | AD9: US$/MM BTU | AE9: US$/MM BTU | AF9: US$ | AG9: Canon
A10: - | B10: I | C10: Servicios | D10: Mes | E10: F1 | F10: Bls | H10: 21812 | J10: 69.0374 | N10: 675.6 | O10: =ROUND(G10*I10,2)+ROUND(H10*J10,2)-K10-L10-M10-N10 -> 1505168.2 | P10: =ROUND(18.75%*O10,2) -> 282219.03 | Q10: =ROUND($O10*R10,2) -> 225775.23 | R10: 0.15 | S10: =ROUND($O10*T10,2) -> 56443.81 | T10: 0.0375 | U10: =IF($F10&"/Día"=W$9,SUM($G10:$H10),"") -> 21812 | V10: =IF(U10<>"",$O10,"") -> 1505168.2 | W10: =IF($F10&"/Día"=W$9,ROUND(U10/$W$1,1),"") -> 727.1 | X10: =IF(U10=0,0,IF($F10&"/Día"=W$9,ROUND(V10/U10,4),"")) -> 69.0064 | Y10: =IF(U10=0,0,IF($F10&"/Día"=W$9,ROUND(Z10/U10,4),"")) -> 12.9387 | Z10: =IF(U10<>"",$P10,"") -> 282219.03 | AA10: =IF($F10&"/Día"=AC$9,SUM($G10:$H10),"") | AB10: =IF(AA10<>"",$O10,"") | AC10: =IF($F10&"/Día"=AC$9,ROUND(AA10/$W$1,1),"") | AD10: =IF(AA10=0,0,IF($F10&"/Día"=AC$9,ROUND(AB10/AA10,4),"")) | AE10: =IF(AA10=0,0,IF($F10&"/Día"=AC$9,ROUND(AF10/AA10,4),"")) | AF10: =IF(AA10<>"",$P10,"")
